Attaching to ft_transcendence_backend_1
[36mbackend_1   |[0m /usr/local/lib/python3.12/site-packages/django/core/management/commands/makemigrations.py:160: RuntimeWarning: Got an error checking a consistent migration history performed for database connection 'default': connection to server at "localhost" (127.0.0.1), port 5432 failed: Connection refused
[36mbackend_1   |[0m 	Is the server running on that host and accepting TCP/IP connections?
[36mbackend_1   |[0m connection to server at "localhost" (::1), port 5432 failed: Cannot assign requested address
[36mbackend_1   |[0m 	Is the server running on that host and accepting TCP/IP connections?
[36mbackend_1   |[0m 
[36mbackend_1   |[0m   warnings.warn(
[36mbackend_1   |[0m No changes detected
[36mbackend_1   |[0m Traceback (most recent call last):
[36mbackend_1   |[0m   File "/usr/local/lib/python3.12/site-packages/django/db/backends/base/base.py", line 275, in ensure_connection
[36mbackend_1   |[0m     self.connect()
[36mbackend_1   |[0m   File "/usr/local/lib/python3.12/site-packages/django/utils/asyncio.py", line 26, in inner
[36mbackend_1   |[0m     return func(*args, **kwargs)
[36mbackend_1   |[0m            ^^^^^^^^^^^^^^^^^^^^^
[36mbackend_1   |[0m   File "/usr/local/lib/python3.12/site-packages/django/db/backends/base/base.py", line 256, in connect
[36mbackend_1   |[0m     self.connection = self.get_new_connection(conn_params)
[36mbackend_1   |[0m                       ^^^^^^^^^^^^^^^^^^^^^^^^^^^^^^^^^^^^
[36mbackend_1   |[0m   File "/usr/local/lib/python3.12/site-packages/django/utils/asyncio.py", line 26, in inner
[36mbackend_1   |[0m     return func(*args, **kwargs)
[36mbackend_1   |[0m            ^^^^^^^^^^^^^^^^^^^^^
[36mbackend_1   |[0m   File "/usr/local/lib/python3.12/site-packages/django/db/backends/postgresql/base.py", line 277, in get_new_connection
[36mbackend_1   |[0m     connection = self.Database.connect(**conn_params)
[36mbackend_1   |[0m                  ^^^^^^^^^^^^^^^^^^^^^^^^^^^^^^^^^^^^
[36mbackend_1   |[0m   File "/usr/local/lib/python3.12/site-packages/psycopg2/__init__.py", line 122, in connect
[36mbackend_1   |[0m     conn = _connect(dsn, connection_factory=connection_factory, **kwasync)
[36mbackend_1   |[0m            ^^^^^^^^^^^^^^^^^^^^^^^^^^^^^^^^^^^^^^^^^^^^^^^^^^^^^^^^^^^^^^^
[36mbackend_1   |[0m psycopg2.OperationalError: connection to server at "localhost" (127.0.0.1), port 5432 failed: Connection refused
[36mbackend_1   |[0m 	Is the server running on that host and accepting TCP/IP connections?
[36mbackend_1   |[0m connection to server at "localhost" (::1), port 5432 failed: Cannot assign requested address
[36mbackend_1   |[0m 	Is the server running on that host and accepting TCP/IP connections?
[36mbackend_1   |[0m 
[36mbackend_1   |[0m 
[36mbackend_1   |[0m The above exception was the direct cause of the following exception:
[36mbackend_1   |[0m 
[36mbackend_1   |[0m Traceback (most recent call last):
[36mbackend_1   |[0m   File "/app/manage.py", line 22, in <module>
[36mbackend_1   |[0m     main()
[36mbackend_1   |[0m   File "/app/manage.py", line 18, in main
[36mbackend_1   |[0m     execute_from_command_line(sys.argv)
[36mbackend_1   |[0m   File "/usr/local/lib/python3.12/site-packages/django/core/management/__init__.py", line 442, in execute_from_command_line
[36mbackend_1   |[0m     utility.execute()
[36mbackend_1   |[0m   File "/usr/local/lib/python3.12/site-packages/django/core/management/__init__.py", line 436, in execute
[36mbackend_1   |[0m     self.fetch_command(subcommand).run_from_argv(self.argv)
[36mbackend_1   |[0m   File "/usr/local/lib/python3.12/site-packages/django/core/management/base.py", line 413, in run_from_argv
[36mbackend_1   |[0m     self.execute(*args, **cmd_options)
[36mbackend_1   |[0m   File "/usr/local/lib/python3.12/site-packages/django/core/management/base.py", line 459, in execute
[36mbackend_1   |[0m     output = self.handle(*args, **options)
[36mbackend_1   |[0m              ^^^^^^^^^^^^^^^^^^^^^^^^^^^^^
[36mbackend_1   |[0m   File "/usr/local/lib/python3.12/site-packages/django/core/management/base.py", line 107, in wrapper
[36mbackend_1   |[0m     res = handle_func(*args, **kwargs)
[36mbackend_1   |[0m           ^^^^^^^^^^^^^^^^^^^^^^^^^^^^
[36mbackend_1   |[0m   File "/usr/local/lib/python3.12/site-packages/django/core/management/commands/migrate.py", line 100, in handle
[36mbackend_1   |[0m     self.check(databases=[database])
[36mbackend_1   |[0m   File "/usr/local/lib/python3.12/site-packages/django/core/management/base.py", line 486, in check
[36mbackend_1   |[0m     all_issues = checks.run_checks(
[36mbackend_1   |[0m                  ^^^^^^^^^^^^^^^^^^
[36mbackend_1   |[0m   File "/usr/local/lib/python3.12/site-packages/django/core/checks/registry.py", line 88, in run_checks
[36mbackend_1   |[0m     new_errors = check(app_configs=app_configs, databases=databases)
[36mbackend_1   |[0m                  ^^^^^^^^^^^^^^^^^^^^^^^^^^^^^^^^^^^^^^^^^^^^^^^^^^^
[36mbackend_1   |[0m   File "/usr/local/lib/python3.12/site-packages/django/core/checks/model_checks.py", line 36, in check_all_models
[36mbackend_1   |[0m     errors.extend(model.check(**kwargs))
[36mbackend_1   |[0m                   ^^^^^^^^^^^^^^^^^^^^^
[36mbackend_1   |[0m   File "/usr/local/lib/python3.12/site-packages/django/db/models/base.py", line 1610, in check
[36mbackend_1   |[0m     *cls._check_constraints(databases),
[36mbackend_1   |[0m      ^^^^^^^^^^^^^^^^^^^^^^^^^^^^^^^^^
[36mbackend_1   |[0m   File "/usr/local/lib/python3.12/site-packages/django/db/models/base.py", line 2460, in _check_constraints
[36mbackend_1   |[0m     connection.features.supports_nulls_distinct_unique_constraints
[36mbackend_1   |[0m   File "/usr/local/lib/python3.12/site-packages/django/utils/functional.py", line 47, in __get__
[36mbackend_1   |[0m     res = instance.__dict__[self.name] = self.func(instance)
[36mbackend_1   |[0m                                          ^^^^^^^^^^^^^^^^^^^
[36mbackend_1   |[0m   File "/usr/local/lib/python3.12/site-packages/django/db/backends/postgresql/features.py", line 141, in is_postgresql_15
[36mbackend_1   |[0m     return self.connection.pg_version >= 150000
[36mbackend_1   |[0m            ^^^^^^^^^^^^^^^^^^^^^^^^^^
[36mbackend_1   |[0m   File "/usr/local/lib/python3.12/site-packages/django/utils/functional.py", line 47, in __get__
[36mbackend_1   |[0m     res = instance.__dict__[self.name] = self.func(instance)
[36mbackend_1   |[0m                                          ^^^^^^^^^^^^^^^^^^^
[36mbackend_1   |[0m   File "/usr/local/lib/python3.12/site-packages/django/db/backends/postgresql/base.py", line 438, in pg_version
[36mbackend_1   |[0m     with self.temporary_connection():
[36mbackend_1   |[0m   File "/usr/local/lib/python3.12/contextlib.py", line 137, in __enter__
[36mbackend_1   |[0m     return next(self.gen)
[36mbackend_1   |[0m            ^^^^^^^^^^^^^^
[36mbackend_1   |[0m   File "/usr/local/lib/python3.12/site-packages/django/db/backends/base/base.py", line 691, in temporary_connection
[36mbackend_1   |[0m     with self.cursor() as cursor:
[36mbackend_1   |[0m          ^^^^^^^^^^^^^
[36mbackend_1   |[0m   File "/usr/local/lib/python3.12/site-packages/django/utils/asyncio.py", line 26, in inner
[36mbackend_1   |[0m     return func(*args, **kwargs)
[36mbackend_1   |[0m            ^^^^^^^^^^^^^^^^^^^^^
[36mbackend_1   |[0m   File "/usr/local/lib/python3.12/site-packages/django/db/backends/base/base.py", line 316, in cursor
[36mbackend_1   |[0m     return self._cursor()
[36mbackend_1   |[0m            ^^^^^^^^^^^^^^
[36mbackend_1   |[0m   File "/usr/local/lib/python3.12/site-packages/django/db/backends/base/base.py", line 292, in _cursor
[36mbackend_1   |[0m     self.ensure_connection()
[36mbackend_1   |[0m   File "/usr/local/lib/python3.12/site-packages/django/utils/asyncio.py", line 26, in inner
[36mbackend_1   |[0m     return func(*args, **kwargs)
[36mbackend_1   |[0m            ^^^^^^^^^^^^^^^^^^^^^
[36mbackend_1   |[0m   File "/usr/local/lib/python3.12/site-packages/django/db/backends/base/base.py", line 274, in ensure_connection
[36mbackend_1   |[0m     with self.wrap_database_errors:
[36mbackend_1   |[0m   File "/usr/local/lib/python3.12/site-packages/django/db/utils.py", line 91, in __exit__
[36mbackend_1   |[0m     raise dj_exc_value.with_traceback(traceback) from exc_value
[36mbackend_1   |[0m   File "/usr/local/lib/python3.12/site-packages/django/db/backends/base/base.py", line 275, in ensure_connection
[36mbackend_1   |[0m     self.connect()
[36mbackend_1   |[0m   File "/usr/local/lib/python3.12/site-packages/django/utils/asyncio.py", line 26, in inner
[36mbackend_1   |[0m     return func(*args, **kwargs)
[36mbackend_1   |[0m            ^^^^^^^^^^^^^^^^^^^^^
[36mbackend_1   |[0m   File "/usr/local/lib/python3.12/site-packages/django/db/backends/base/base.py", line 256, in connect
[36mbackend_1   |[0m     self.connection = self.get_new_connection(conn_params)
[36mbackend_1   |[0m                       ^^^^^^^^^^^^^^^^^^^^^^^^^^^^^^^^^^^^
[36mbackend_1   |[0m   File "/usr/local/lib/python3.12/site-packages/django/utils/asyncio.py", line 26, in inner
[36mbackend_1   |[0m     return func(*args, **kwargs)
[36mbackend_1   |[0m            ^^^^^^^^^^^^^^^^^^^^^
[36mbackend_1   |[0m   File "/usr/local/lib/python3.12/site-packages/django/db/backends/postgresql/base.py", line 277, in get_new_connection
[36mbackend_1   |[0m     connection = self.Database.connect(**conn_params)
[36mbackend_1   |[0m                  ^^^^^^^^^^^^^^^^^^^^^^^^^^^^^^^^^^^^
[36mbackend_1   |[0m   File "/usr/local/lib/python3.12/site-packages/psycopg2/__init__.py", line 122, in connect
[36mbackend_1   |[0m     conn = _connect(dsn, connection_factory=connection_factory, **kwasync)
[36mbackend_1   |[0m            ^^^^^^^^^^^^^^^^^^^^^^^^^^^^^^^^^^^^^^^^^^^^^^^^^^^^^^^^^^^^^^^
[36mbackend_1   |[0m django.db.utils.OperationalError: connection to server at "localhost" (127.0.0.1), port 5432 failed: Connection refused
[36mbackend_1   |[0m 	Is the server running on that host and accepting TCP/IP connections?
[36mbackend_1   |[0m connection to server at "localhost" (::1), port 5432 failed: Cannot assign requested address
[36mbackend_1   |[0m 	Is the server running on that host and accepting TCP/IP connections?
[36mbackend_1   |[0m 
[36mbackend_1   |[0m /usr/local/lib/python3.12/site-packages/django/core/management/commands/makemigrations.py:160: RuntimeWarning: Got an error checking a consistent migration history performed for database connection 'default': connection to server at "localhost" (127.0.0.1), port 5432 failed: Connection refused
[36mbackend_1   |[0m 	Is the server running on that host and accepting TCP/IP connections?
[36mbackend_1   |[0m connection to server at "localhost" (::1), port 5432 failed: Cannot assign requested address
[36mbackend_1   |[0m 	Is the server running on that host and accepting TCP/IP connections?
[36mbackend_1   |[0m 
[36mbackend_1   |[0m   warnings.warn(
[36mbackend_1   |[0m No changes detected
[36mbackend_1   |[0m Traceback (most recent call last):
[36mbackend_1   |[0m   File "/usr/local/lib/python3.12/site-packages/django/db/backends/base/base.py", line 275, in ensure_connection
[36mbackend_1   |[0m     self.connect()
[36mbackend_1   |[0m   File "/usr/local/lib/python3.12/site-packages/django/utils/asyncio.py", line 26, in inner
[36mbackend_1   |[0m     return func(*args, **kwargs)
[36mbackend_1   |[0m            ^^^^^^^^^^^^^^^^^^^^^
[36mbackend_1   |[0m   File "/usr/local/lib/python3.12/site-packages/django/db/backends/base/base.py", line 256, in connect
[36mbackend_1   |[0m     self.connection = self.get_new_connection(conn_params)
[36mbackend_1   |[0m                       ^^^^^^^^^^^^^^^^^^^^^^^^^^^^^^^^^^^^
[36mbackend_1   |[0m   File "/usr/local/lib/python3.12/site-packages/django/utils/asyncio.py", line 26, in inner
[36mbackend_1   |[0m     return func(*args, **kwargs)
[36mbackend_1   |[0m            ^^^^^^^^^^^^^^^^^^^^^
[36mbackend_1   |[0m   File "/usr/local/lib/python3.12/site-packages/django/db/backends/postgresql/base.py", line 277, in get_new_connection
[36mbackend_1   |[0m     connection = self.Database.connect(**conn_params)
[36mbackend_1   |[0m                  ^^^^^^^^^^^^^^^^^^^^^^^^^^^^^^^^^^^^
[36mbackend_1   |[0m   File "/usr/local/lib/python3.12/site-packages/psycopg2/__init__.py", line 122, in connect
[36mbackend_1   |[0m     conn = _connect(dsn, connection_factory=connection_factory, **kwasync)
[36mbackend_1   |[0m            ^^^^^^^^^^^^^^^^^^^^^^^^^^^^^^^^^^^^^^^^^^^^^^^^^^^^^^^^^^^^^^^
[36mbackend_1   |[0m psycopg2.OperationalError: connection to server at "localhost" (127.0.0.1), port 5432 failed: Connection refused
[36mbackend_1   |[0m 	Is the server running on that host and accepting TCP/IP connections?
[36mbackend_1   |[0m connection to server at "localhost" (::1), port 5432 failed: Cannot assign requested address
[36mbackend_1   |[0m 	Is the server running on that host and accepting TCP/IP connections?
[36mbackend_1   |[0m 
[36mbackend_1   |[0m 
[36mbackend_1   |[0m The above exception was the direct cause of the following exception:
[36mbackend_1   |[0m 
[36mbackend_1   |[0m Traceback (most recent call last):
[36mbackend_1   |[0m   File "/app/manage.py", line 22, in <module>
[36mbackend_1   |[0m     main()
[36mbackend_1   |[0m   File "/app/manage.py", line 18, in main
[36mbackend_1   |[0m     execute_from_command_line(sys.argv)
[36mbackend_1   |[0m   File "/usr/local/lib/python3.12/site-packages/django/core/management/__init__.py", line 442, in execute_from_command_line
[36mbackend_1   |[0m     utility.execute()
[36mbackend_1   |[0m   File "/usr/local/lib/python3.12/site-packages/django/core/management/__init__.py", line 436, in execute
[36mbackend_1   |[0m     self.fetch_command(subcommand).run_from_argv(self.argv)
[36mbackend_1   |[0m   File "/usr/local/lib/python3.12/site-packages/django/core/management/base.py", line 413, in run_from_argv
[36mbackend_1   |[0m     self.execute(*args, **cmd_options)
[36mbackend_1   |[0m   File "/usr/local/lib/python3.12/site-packages/django/core/management/base.py", line 459, in execute
[36mbackend_1   |[0m     output = self.handle(*args, **options)
[36mbackend_1   |[0m              ^^^^^^^^^^^^^^^^^^^^^^^^^^^^^
[36mbackend_1   |[0m   File "/usr/local/lib/python3.12/site-packages/django/core/management/base.py", line 107, in wrapper
[36mbackend_1   |[0m     res = handle_func(*args, **kwargs)
[36mbackend_1   |[0m           ^^^^^^^^^^^^^^^^^^^^^^^^^^^^
[36mbackend_1   |[0m   File "/usr/local/lib/python3.12/site-packages/django/core/management/commands/migrate.py", line 100, in handle
[36mbackend_1   |[0m     self.check(databases=[database])
[36mbackend_1   |[0m   File "/usr/local/lib/python3.12/site-packages/django/core/management/base.py", line 486, in check
[36mbackend_1   |[0m     all_issues = checks.run_checks(
[36mbackend_1   |[0m                  ^^^^^^^^^^^^^^^^^^
[36mbackend_1   |[0m   File "/usr/local/lib/python3.12/site-packages/django/core/checks/registry.py", line 88, in run_checks
[36mbackend_1   |[0m     new_errors = check(app_configs=app_configs, databases=databases)
[36mbackend_1   |[0m                  ^^^^^^^^^^^^^^^^^^^^^^^^^^^^^^^^^^^^^^^^^^^^^^^^^^^
[36mbackend_1   |[0m   File "/usr/local/lib/python3.12/site-packages/django/core/checks/model_checks.py", line 36, in check_all_models
[36mbackend_1   |[0m     errors.extend(model.check(**kwargs))
[36mbackend_1   |[0m                   ^^^^^^^^^^^^^^^^^^^^^
[36mbackend_1   |[0m   File "/usr/local/lib/python3.12/site-packages/django/db/models/base.py", line 1610, in check
[36mbackend_1   |[0m     *cls._check_constraints(databases),
[36mbackend_1   |[0m      ^^^^^^^^^^^^^^^^^^^^^^^^^^^^^^^^^
[36mbackend_1   |[0m   File "/usr/local/lib/python3.12/site-packages/django/db/models/base.py", line 2460, in _check_constraints
[36mbackend_1   |[0m     connection.features.supports_nulls_distinct_unique_constraints
[36mbackend_1   |[0m   File "/usr/local/lib/python3.12/site-packages/django/utils/functional.py", line 47, in __get__
[36mbackend_1   |[0m     res = instance.__dict__[self.name] = self.func(instance)
[36mbackend_1   |[0m                                          ^^^^^^^^^^^^^^^^^^^
[36mbackend_1   |[0m   File "/usr/local/lib/python3.12/site-packages/django/db/backends/postgresql/features.py", line 141, in is_postgresql_15
[36mbackend_1   |[0m     return self.connection.pg_version >= 150000
[36mbackend_1   |[0m            ^^^^^^^^^^^^^^^^^^^^^^^^^^
[36mbackend_1   |[0m   File "/usr/local/lib/python3.12/site-packages/django/utils/functional.py", line 47, in __get__
[36mbackend_1   |[0m     res = instance.__dict__[self.name] = self.func(instance)
[36mbackend_1   |[0m                                          ^^^^^^^^^^^^^^^^^^^
[36mbackend_1   |[0m   File "/usr/local/lib/python3.12/site-packages/django/db/backends/postgresql/base.py", line 438, in pg_version
[36mbackend_1   |[0m     with self.temporary_connection():
[36mbackend_1   |[0m   File "/usr/local/lib/python3.12/contextlib.py", line 137, in __enter__
[36mbackend_1   |[0m     return next(self.gen)
[36mbackend_1   |[0m            ^^^^^^^^^^^^^^
[36mbackend_1   |[0m   File "/usr/local/lib/python3.12/site-packages/django/db/backends/base/base.py", line 691, in temporary_connection
[36mbackend_1   |[0m     with self.cursor() as cursor:
[36mbackend_1   |[0m          ^^^^^^^^^^^^^
[36mbackend_1   |[0m   File "/usr/local/lib/python3.12/site-packages/django/utils/asyncio.py", line 26, in inner
[36mbackend_1   |[0m     return func(*args, **kwargs)
[36mbackend_1   |[0m            ^^^^^^^^^^^^^^^^^^^^^
[36mbackend_1   |[0m   File "/usr/local/lib/python3.12/site-packages/django/db/backends/base/base.py", line 316, in cursor
[36mbackend_1   |[0m     return self._cursor()
[36mbackend_1   |[0m            ^^^^^^^^^^^^^^
[36mbackend_1   |[0m   File "/usr/local/lib/python3.12/site-packages/django/db/backends/base/base.py", line 292, in _cursor
[36mbackend_1   |[0m     self.ensure_connection()
[36mbackend_1   |[0m   File "/usr/local/lib/python3.12/site-packages/django/utils/asyncio.py", line 26, in inner
[36mbackend_1   |[0m     return func(*args, **kwargs)
[36mbackend_1   |[0m            ^^^^^^^^^^^^^^^^^^^^^
[36mbackend_1   |[0m   File "/usr/local/lib/python3.12/site-packages/django/db/backends/base/base.py", line 274, in ensure_connection
[36mbackend_1   |[0m     with self.wrap_database_errors:
[36mbackend_1   |[0m   File "/usr/local/lib/python3.12/site-packages/django/db/utils.py", line 91, in __exit__
[36mbackend_1   |[0m     raise dj_exc_value.with_traceback(traceback) from exc_value
[36mbackend_1   |[0m   File "/usr/local/lib/python3.12/site-packages/django/db/backends/base/base.py", line 275, in ensure_connection
[36mbackend_1   |[0m     self.connect()
[36mbackend_1   |[0m   File "/usr/local/lib/python3.12/site-packages/django/utils/asyncio.py", line 26, in inner
[36mbackend_1   |[0m     return func(*args, **kwargs)
[36mbackend_1   |[0m            ^^^^^^^^^^^^^^^^^^^^^
[36mbackend_1   |[0m   File "/usr/local/lib/python3.12/site-packages/django/db/backends/base/base.py", line 256, in connect
[36mbackend_1   |[0m     self.connection = self.get_new_connection(conn_params)
[36mbackend_1   |[0m                       ^^^^^^^^^^^^^^^^^^^^^^^^^^^^^^^^^^^^
[36mbackend_1   |[0m   File "/usr/local/lib/python3.12/site-packages/django/utils/asyncio.py", line 26, in inner
[36mbackend_1   |[0m     return func(*args, **kwargs)
[36mbackend_1   |[0m            ^^^^^^^^^^^^^^^^^^^^^
[36mbackend_1   |[0m   File "/usr/local/lib/python3.12/site-packages/django/db/backends/postgresql/base.py", line 277, in get_new_connection
[36mbackend_1   |[0m     connection = self.Database.connect(**conn_params)
[36mbackend_1   |[0m                  ^^^^^^^^^^^^^^^^^^^^^^^^^^^^^^^^^^^^
[36mbackend_1   |[0m   File "/usr/local/lib/python3.12/site-packages/psycopg2/__init__.py", line 122, in connect
[36mbackend_1   |[0m     conn = _connect(dsn, connection_factory=connection_factory, **kwasync)
[36mbackend_1   |[0m            ^^^^^^^^^^^^^^^^^^^^^^^^^^^^^^^^^^^^^^^^^^^^^^^^^^^^^^^^^^^^^^^
[36mbackend_1   |[0m django.db.utils.OperationalError: connection to server at "localhost" (127.0.0.1), port 5432 failed: Connection refused
[36mbackend_1   |[0m 	Is the server running on that host and accepting TCP/IP connections?
[36mbackend_1   |[0m connection to server at "localhost" (::1), port 5432 failed: Cannot assign requested address
[36mbackend_1   |[0m 	Is the server running on that host and accepting TCP/IP connections?
[36mbackend_1   |[0m 
[36mbackend_1   |[0m /usr/local/lib/python3.12/site-packages/django/core/management/commands/makemigrations.py:160: RuntimeWarning: Got an error checking a consistent migration history performed for database connection 'default': connection to server at "localhost" (127.0.0.1), port 5432 failed: Connection refused
[36mbackend_1   |[0m 	Is the server running on that host and accepting TCP/IP connections?
[36mbackend_1   |[0m connection to server at "localhost" (::1), port 5432 failed: Cannot assign requested address
[36mbackend_1   |[0m 	Is the server running on that host and accepting TCP/IP connections?
[36mbackend_1   |[0m 
[36mbackend_1   |[0m   warnings.warn(
[36mbackend_1   |[0m No changes detected
[36mbackend_1   |[0m Traceback (most recent call last):
[36mbackend_1   |[0m   File "/usr/local/lib/python3.12/site-packages/django/db/backends/base/base.py", line 275, in ensure_connection
[36mbackend_1   |[0m     self.connect()
[36mbackend_1   |[0m   File "/usr/local/lib/python3.12/site-packages/django/utils/asyncio.py", line 26, in inner
[36mbackend_1   |[0m     return func(*args, **kwargs)
[36mbackend_1   |[0m            ^^^^^^^^^^^^^^^^^^^^^
[36mbackend_1   |[0m   File "/usr/local/lib/python3.12/site-packages/django/db/backends/base/base.py", line 256, in connect
[36mbackend_1   |[0m     self.connection = self.get_new_connection(conn_params)
[36mbackend_1   |[0m                       ^^^^^^^^^^^^^^^^^^^^^^^^^^^^^^^^^^^^
[36mbackend_1   |[0m   File "/usr/local/lib/python3.12/site-packages/django/utils/asyncio.py", line 26, in inner
[36mbackend_1   |[0m     return func(*args, **kwargs)
[36mbackend_1   |[0m            ^^^^^^^^^^^^^^^^^^^^^
[36mbackend_1   |[0m   File "/usr/local/lib/python3.12/site-packages/django/db/backends/postgresql/base.py", line 277, in get_new_connection
[36mbackend_1   |[0m     connection = self.Database.connect(**conn_params)
[36mbackend_1   |[0m                  ^^^^^^^^^^^^^^^^^^^^^^^^^^^^^^^^^^^^
[36mbackend_1   |[0m   File "/usr/local/lib/python3.12/site-packages/psycopg2/__init__.py", line 122, in connect
[36mbackend_1   |[0m     conn = _connect(dsn, connection_factory=connection_factory, **kwasync)
[36mbackend_1   |[0m            ^^^^^^^^^^^^^^^^^^^^^^^^^^^^^^^^^^^^^^^^^^^^^^^^^^^^^^^^^^^^^^^
[36mbackend_1   |[0m psycopg2.OperationalError: connection to server at "localhost" (127.0.0.1), port 5432 failed: Connection refused
[36mbackend_1   |[0m 	Is the server running on that host and accepting TCP/IP connections?
[36mbackend_1   |[0m connection to server at "localhost" (::1), port 5432 failed: Cannot assign requested address
[36mbackend_1   |[0m 	Is the server running on that host and accepting TCP/IP connections?
[36mbackend_1   |[0m 
[36mbackend_1   |[0m 
[36mbackend_1   |[0m The above exception was the direct cause of the following exception:
[36mbackend_1   |[0m 
[36mbackend_1   |[0m Traceback (most recent call last):
[36mbackend_1   |[0m   File "/app/manage.py", line 22, in <module>
[36mbackend_1   |[0m     main()
[36mbackend_1   |[0m   File "/app/manage.py", line 18, in main
[36mbackend_1   |[0m     execute_from_command_line(sys.argv)
[36mbackend_1   |[0m   File "/usr/local/lib/python3.12/site-packages/django/core/management/__init__.py", line 442, in execute_from_command_line
[36mbackend_1   |[0m     utility.execute()
[36mbackend_1   |[0m   File "/usr/local/lib/python3.12/site-packages/django/core/management/__init__.py", line 436, in execute
[36mbackend_1   |[0m     self.fetch_command(subcommand).run_from_argv(self.argv)
[36mbackend_1   |[0m   File "/usr/local/lib/python3.12/site-packages/django/core/management/base.py", line 413, in run_from_argv
[36mbackend_1   |[0m     self.execute(*args, **cmd_options)
[36mbackend_1   |[0m   File "/usr/local/lib/python3.12/site-packages/django/core/management/base.py", line 459, in execute
[36mbackend_1   |[0m     output = self.handle(*args, **options)
[36mbackend_1   |[0m              ^^^^^^^^^^^^^^^^^^^^^^^^^^^^^
[36mbackend_1   |[0m   File "/usr/local/lib/python3.12/site-packages/django/core/management/base.py", line 107, in wrapper
[36mbackend_1   |[0m     res = handle_func(*args, **kwargs)
[36mbackend_1   |[0m           ^^^^^^^^^^^^^^^^^^^^^^^^^^^^
[36mbackend_1   |[0m   File "/usr/local/lib/python3.12/site-packages/django/core/management/commands/migrate.py", line 100, in handle
[36mbackend_1   |[0m     self.check(databases=[database])
[36mbackend_1   |[0m   File "/usr/local/lib/python3.12/site-packages/django/core/management/base.py", line 486, in check
[36mbackend_1   |[0m     all_issues = checks.run_checks(
[36mbackend_1   |[0m                  ^^^^^^^^^^^^^^^^^^
[36mbackend_1   |[0m   File "/usr/local/lib/python3.12/site-packages/django/core/checks/registry.py", line 88, in run_checks
[36mbackend_1   |[0m     new_errors = check(app_configs=app_configs, databases=databases)
[36mbackend_1   |[0m                  ^^^^^^^^^^^^^^^^^^^^^^^^^^^^^^^^^^^^^^^^^^^^^^^^^^^
[36mbackend_1   |[0m   File "/usr/local/lib/python3.12/site-packages/django/core/checks/model_checks.py", line 36, in check_all_models
[36mbackend_1   |[0m     errors.extend(model.check(**kwargs))
[36mbackend_1   |[0m                   ^^^^^^^^^^^^^^^^^^^^^
[36mbackend_1   |[0m   File "/usr/local/lib/python3.12/site-packages/django/db/models/base.py", line 1610, in check
[36mbackend_1   |[0m     *cls._check_constraints(databases),
[36mbackend_1   |[0m      ^^^^^^^^^^^^^^^^^^^^^^^^^^^^^^^^^
[36mbackend_1   |[0m   File "/usr/local/lib/python3.12/site-packages/django/db/models/base.py", line 2460, in _check_constraints
[36mbackend_1   |[0m     connection.features.supports_nulls_distinct_unique_constraints
[36mbackend_1   |[0m   File "/usr/local/lib/python3.12/site-packages/django/utils/functional.py", line 47, in __get__
[36mbackend_1   |[0m     res = instance.__dict__[self.name] = self.func(instance)
[36mbackend_1   |[0m                                          ^^^^^^^^^^^^^^^^^^^
[36mbackend_1   |[0m   File "/usr/local/lib/python3.12/site-packages/django/db/backends/postgresql/features.py", line 141, in is_postgresql_15
[36mbackend_1   |[0m     return self.connection.pg_version >= 150000
[36mbackend_1   |[0m            ^^^^^^^^^^^^^^^^^^^^^^^^^^
[36mbackend_1   |[0m   File "/usr/local/lib/python3.12/site-packages/django/utils/functional.py", line 47, in __get__
[36mbackend_1   |[0m     res = instance.__dict__[self.name] = self.func(instance)
[36mbackend_1   |[0m                                          ^^^^^^^^^^^^^^^^^^^
[36mbackend_1   |[0m   File "/usr/local/lib/python3.12/site-packages/django/db/backends/postgresql/base.py", line 438, in pg_version
[36mbackend_1   |[0m     with self.temporary_connection():
[36mbackend_1   |[0m   File "/usr/local/lib/python3.12/contextlib.py", line 137, in __enter__
[36mbackend_1   |[0m     return next(self.gen)
[36mbackend_1   |[0m            ^^^^^^^^^^^^^^
[36mbackend_1   |[0m   File "/usr/local/lib/python3.12/site-packages/django/db/backends/base/base.py", line 691, in temporary_connection
[36mbackend_1   |[0m     with self.cursor() as cursor:
[36mbackend_1   |[0m          ^^^^^^^^^^^^^
[36mbackend_1   |[0m   File "/usr/local/lib/python3.12/site-packages/django/utils/asyncio.py", line 26, in inner
[36mbackend_1   |[0m     return func(*args, **kwargs)
[36mbackend_1   |[0m            ^^^^^^^^^^^^^^^^^^^^^
[36mbackend_1   |[0m   File "/usr/local/lib/python3.12/site-packages/django/db/backends/base/base.py", line 316, in cursor
[36mbackend_1   |[0m     return self._cursor()
[36mbackend_1   |[0m            ^^^^^^^^^^^^^^
[36mbackend_1   |[0m   File "/usr/local/lib/python3.12/site-packages/django/db/backends/base/base.py", line 292, in _cursor
[36mbackend_1   |[0m     self.ensure_connection()
[36mbackend_1   |[0m   File "/usr/local/lib/python3.12/site-packages/django/utils/asyncio.py", line 26, in inner
[36mbackend_1   |[0m     return func(*args, **kwargs)
[36mbackend_1   |[0m            ^^^^^^^^^^^^^^^^^^^^^
[36mbackend_1   |[0m   File "/usr/local/lib/python3.12/site-packages/django/db/backends/base/base.py", line 274, in ensure_connection
[36mbackend_1   |[0m     with self.wrap_database_errors:
[36mbackend_1   |[0m   File "/usr/local/lib/python3.12/site-packages/django/db/utils.py", line 91, in __exit__
[36mbackend_1   |[0m     raise dj_exc_value.with_traceback(traceback) from exc_value
[36mbackend_1   |[0m   File "/usr/local/lib/python3.12/site-packages/django/db/backends/base/base.py", line 275, in ensure_connection
[36mbackend_1   |[0m     self.connect()
[36mbackend_1   |[0m   File "/usr/local/lib/python3.12/site-packages/django/utils/asyncio.py", line 26, in inner
[36mbackend_1   |[0m     return func(*args, **kwargs)
[36mbackend_1   |[0m            ^^^^^^^^^^^^^^^^^^^^^
[36mbackend_1   |[0m   File "/usr/local/lib/python3.12/site-packages/django/db/backends/base/base.py", line 256, in connect
[36mbackend_1   |[0m     self.connection = self.get_new_connection(conn_params)
[36mbackend_1   |[0m                       ^^^^^^^^^^^^^^^^^^^^^^^^^^^^^^^^^^^^
[36mbackend_1   |[0m   File "/usr/local/lib/python3.12/site-packages/django/utils/asyncio.py", line 26, in inner
[36mbackend_1   |[0m     return func(*args, **kwargs)
[36mbackend_1   |[0m            ^^^^^^^^^^^^^^^^^^^^^
[36mbackend_1   |[0m   File "/usr/local/lib/python3.12/site-packages/django/db/backends/postgresql/base.py", line 277, in get_new_connection
[36mbackend_1   |[0m     connection = self.Database.connect(**conn_params)
[36mbackend_1   |[0m                  ^^^^^^^^^^^^^^^^^^^^^^^^^^^^^^^^^^^^
[36mbackend_1   |[0m   File "/usr/local/lib/python3.12/site-packages/psycopg2/__init__.py", line 122, in connect
[36mbackend_1   |[0m     conn = _connect(dsn, connection_factory=connection_factory, **kwasync)
[36mbackend_1   |[0m            ^^^^^^^^^^^^^^^^^^^^^^^^^^^^^^^^^^^^^^^^^^^^^^^^^^^^^^^^^^^^^^^
[36mbackend_1   |[0m django.db.utils.OperationalError: connection to server at "localhost" (127.0.0.1), port 5432 failed: Connection refused
[36mbackend_1   |[0m 	Is the server running on that host and accepting TCP/IP connections?
[36mbackend_1   |[0m connection to server at "localhost" (::1), port 5432 failed: Cannot assign requested address
[36mbackend_1   |[0m 	Is the server running on that host and accepting TCP/IP connections?
[36mbackend_1   |[0m 
[36mbackend_1   |[0m /usr/local/lib/python3.12/site-packages/django/core/management/commands/makemigrations.py:160: RuntimeWarning: Got an error checking a consistent migration history performed for database connection 'default': connection to server at "localhost" (127.0.0.1), port 5432 failed: Connection refused
[36mbackend_1   |[0m 	Is the server running on that host and accepting TCP/IP connections?
[36mbackend_1   |[0m connection to server at "localhost" (::1), port 5432 failed: Cannot assign requested address
[36mbackend_1   |[0m 	Is the server running on that host and accepting TCP/IP connections?
[36mbackend_1   |[0m 
[36mbackend_1   |[0m   warnings.warn(
[36mbackend_1   |[0m No changes detected
[36mbackend_1   |[0m Traceback (most recent call last):
[36mbackend_1   |[0m   File "/usr/local/lib/python3.12/site-packages/django/db/backends/base/base.py", line 275, in ensure_connection
[36mbackend_1   |[0m     self.connect()
[36mbackend_1   |[0m   File "/usr/local/lib/python3.12/site-packages/django/utils/asyncio.py", line 26, in inner
[36mbackend_1   |[0m     return func(*args, **kwargs)
[36mbackend_1   |[0m            ^^^^^^^^^^^^^^^^^^^^^
[36mbackend_1   |[0m   File "/usr/local/lib/python3.12/site-packages/django/db/backends/base/base.py", line 256, in connect
[36mbackend_1   |[0m     self.connection = self.get_new_connection(conn_params)
[36mbackend_1   |[0m                       ^^^^^^^^^^^^^^^^^^^^^^^^^^^^^^^^^^^^
[36mbackend_1   |[0m   File "/usr/local/lib/python3.12/site-packages/django/utils/asyncio.py", line 26, in inner
[36mbackend_1   |[0m     return func(*args, **kwargs)
[36mbackend_1   |[0m            ^^^^^^^^^^^^^^^^^^^^^
[36mbackend_1   |[0m   File "/usr/local/lib/python3.12/site-packages/django/db/backends/postgresql/base.py", line 277, in get_new_connection
[36mbackend_1   |[0m     connection = self.Database.connect(**conn_params)
[36mbackend_1   |[0m                  ^^^^^^^^^^^^^^^^^^^^^^^^^^^^^^^^^^^^
[36mbackend_1   |[0m   File "/usr/local/lib/python3.12/site-packages/psycopg2/__init__.py", line 122, in connect
[36mbackend_1   |[0m     conn = _connect(dsn, connection_factory=connection_factory, **kwasync)
[36mbackend_1   |[0m            ^^^^^^^^^^^^^^^^^^^^^^^^^^^^^^^^^^^^^^^^^^^^^^^^^^^^^^^^^^^^^^^
[36mbackend_1   |[0m psycopg2.OperationalError: connection to server at "localhost" (127.0.0.1), port 5432 failed: Connection refused
[36mbackend_1   |[0m 	Is the server running on that host and accepting TCP/IP connections?
[36mbackend_1   |[0m connection to server at "localhost" (::1), port 5432 failed: Cannot assign requested address
[36mbackend_1   |[0m 	Is the server running on that host and accepting TCP/IP connections?
[36mbackend_1   |[0m 
[36mbackend_1   |[0m 
[36mbackend_1   |[0m The above exception was the direct cause of the following exception:
[36mbackend_1   |[0m 
[36mbackend_1   |[0m Traceback (most recent call last):
[36mbackend_1   |[0m   File "/app/manage.py", line 22, in <module>
[36mbackend_1   |[0m     main()
[36mbackend_1   |[0m   File "/app/manage.py", line 18, in main
[36mbackend_1   |[0m     execute_from_command_line(sys.argv)
[36mbackend_1   |[0m   File "/usr/local/lib/python3.12/site-packages/django/core/management/__init__.py", line 442, in execute_from_command_line
[36mbackend_1   |[0m     utility.execute()
[36mbackend_1   |[0m   File "/usr/local/lib/python3.12/site-packages/django/core/management/__init__.py", line 436, in execute
[36mbackend_1   |[0m     self.fetch_command(subcommand).run_from_argv(self.argv)
[36mbackend_1   |[0m   File "/usr/local/lib/python3.12/site-packages/django/core/management/base.py", line 413, in run_from_argv
[36mbackend_1   |[0m     self.execute(*args, **cmd_options)
[36mbackend_1   |[0m   File "/usr/local/lib/python3.12/site-packages/django/core/management/base.py", line 459, in execute
[36mbackend_1   |[0m     output = self.handle(*args, **options)
[36mbackend_1   |[0m              ^^^^^^^^^^^^^^^^^^^^^^^^^^^^^
[36mbackend_1   |[0m   File "/usr/local/lib/python3.12/site-packages/django/core/management/base.py", line 107, in wrapper
[36mbackend_1   |[0m     res = handle_func(*args, **kwargs)
[36mbackend_1   |[0m           ^^^^^^^^^^^^^^^^^^^^^^^^^^^^
[36mbackend_1   |[0m   File "/usr/local/lib/python3.12/site-packages/django/core/management/commands/migrate.py", line 100, in handle
[36mbackend_1   |[0m     self.check(databases=[database])
[36mbackend_1   |[0m   File "/usr/local/lib/python3.12/site-packages/django/core/management/base.py", line 486, in check
[36mbackend_1   |[0m     all_issues = checks.run_checks(
[36mbackend_1   |[0m                  ^^^^^^^^^^^^^^^^^^
[36mbackend_1   |[0m   File "/usr/local/lib/python3.12/site-packages/django/core/checks/registry.py", line 88, in run_checks
[36mbackend_1   |[0m     new_errors = check(app_configs=app_configs, databases=databases)
[36mbackend_1   |[0m                  ^^^^^^^^^^^^^^^^^^^^^^^^^^^^^^^^^^^^^^^^^^^^^^^^^^^
[36mbackend_1   |[0m   File "/usr/local/lib/python3.12/site-packages/django/core/checks/model_checks.py", line 36, in check_all_models
[36mbackend_1   |[0m     errors.extend(model.check(**kwargs))
[36mbackend_1   |[0m                   ^^^^^^^^^^^^^^^^^^^^^
[36mbackend_1   |[0m   File "/usr/local/lib/python3.12/site-packages/django/db/models/base.py", line 1610, in check
[36mbackend_1   |[0m     *cls._check_constraints(databases),
[36mbackend_1   |[0m      ^^^^^^^^^^^^^^^^^^^^^^^^^^^^^^^^^
[36mbackend_1   |[0m   File "/usr/local/lib/python3.12/site-packages/django/db/models/base.py", line 2460, in _check_constraints
[36mbackend_1   |[0m     connection.features.supports_nulls_distinct_unique_constraints
[36mbackend_1   |[0m   File "/usr/local/lib/python3.12/site-packages/django/utils/functional.py", line 47, in __get__
[36mbackend_1   |[0m     res = instance.__dict__[self.name] = self.func(instance)
[36mbackend_1   |[0m                                          ^^^^^^^^^^^^^^^^^^^
[36mbackend_1   |[0m   File "/usr/local/lib/python3.12/site-packages/django/db/backends/postgresql/features.py", line 141, in is_postgresql_15
[36mbackend_1   |[0m     return self.connection.pg_version >= 150000
[36mbackend_1   |[0m            ^^^^^^^^^^^^^^^^^^^^^^^^^^
[36mbackend_1   |[0m   File "/usr/local/lib/python3.12/site-packages/django/utils/functional.py", line 47, in __get__
[36mbackend_1   |[0m     res = instance.__dict__[self.name] = self.func(instance)
[36mbackend_1   |[0m                                          ^^^^^^^^^^^^^^^^^^^
[36mbackend_1   |[0m   File "/usr/local/lib/python3.12/site-packages/django/db/backends/postgresql/base.py", line 438, in pg_version
[36mbackend_1   |[0m     with self.temporary_connection():
[36mbackend_1   |[0m   File "/usr/local/lib/python3.12/contextlib.py", line 137, in __enter__
[36mbackend_1   |[0m     return next(self.gen)
[36mbackend_1   |[0m            ^^^^^^^^^^^^^^
[36mbackend_1   |[0m   File "/usr/local/lib/python3.12/site-packages/django/db/backends/base/base.py", line 691, in temporary_connection
[36mbackend_1   |[0m     with self.cursor() as cursor:
[36mbackend_1   |[0m          ^^^^^^^^^^^^^
[36mbackend_1   |[0m   File "/usr/local/lib/python3.12/site-packages/django/utils/asyncio.py", line 26, in inner
[36mbackend_1   |[0m     return func(*args, **kwargs)
[36mbackend_1   |[0m            ^^^^^^^^^^^^^^^^^^^^^
[36mbackend_1   |[0m   File "/usr/local/lib/python3.12/site-packages/django/db/backends/base/base.py", line 316, in cursor
[36mbackend_1   |[0m     return self._cursor()
[36mbackend_1   |[0m            ^^^^^^^^^^^^^^
[36mbackend_1   |[0m   File "/usr/local/lib/python3.12/site-packages/django/db/backends/base/base.py", line 292, in _cursor
[36mbackend_1   |[0m     self.ensure_connection()
[36mbackend_1   |[0m   File "/usr/local/lib/python3.12/site-packages/django/utils/asyncio.py", line 26, in inner
[36mbackend_1   |[0m     return func(*args, **kwargs)
[36mbackend_1   |[0m            ^^^^^^^^^^^^^^^^^^^^^
[36mbackend_1   |[0m   File "/usr/local/lib/python3.12/site-packages/django/db/backends/base/base.py", line 274, in ensure_connection
[36mbackend_1   |[0m     with self.wrap_database_errors:
[36mbackend_1   |[0m   File "/usr/local/lib/python3.12/site-packages/django/db/utils.py", line 91, in __exit__
[36mbackend_1   |[0m     raise dj_exc_value.with_traceback(traceback) from exc_value
[36mbackend_1   |[0m   File "/usr/local/lib/python3.12/site-packages/django/db/backends/base/base.py", line 275, in ensure_connection
[36mbackend_1   |[0m     self.connect()
[36mbackend_1   |[0m   File "/usr/local/lib/python3.12/site-packages/django/utils/asyncio.py", line 26, in inner
[36mbackend_1   |[0m     return func(*args, **kwargs)
[36mbackend_1   |[0m            ^^^^^^^^^^^^^^^^^^^^^
[36mbackend_1   |[0m   File "/usr/local/lib/python3.12/site-packages/django/db/backends/base/base.py", line 256, in connect
[36mbackend_1   |[0m     self.connection = self.get_new_connection(conn_params)
[36mbackend_1   |[0m                       ^^^^^^^^^^^^^^^^^^^^^^^^^^^^^^^^^^^^
[36mbackend_1   |[0m   File "/usr/local/lib/python3.12/site-packages/django/utils/asyncio.py", line 26, in inner
[36mbackend_1   |[0m     return func(*args, **kwargs)
[36mbackend_1   |[0m            ^^^^^^^^^^^^^^^^^^^^^
[36mbackend_1   |[0m   File "/usr/local/lib/python3.12/site-packages/django/db/backends/postgresql/base.py", line 277, in get_new_connection
[36mbackend_1   |[0m     connection = self.Database.connect(**conn_params)
[36mbackend_1   |[0m                  ^^^^^^^^^^^^^^^^^^^^^^^^^^^^^^^^^^^^
[36mbackend_1   |[0m   File "/usr/local/lib/python3.12/site-packages/psycopg2/__init__.py", line 122, in connect
[36mbackend_1   |[0m     conn = _connect(dsn, connection_factory=connection_factory, **kwasync)
[36mbackend_1   |[0m            ^^^^^^^^^^^^^^^^^^^^^^^^^^^^^^^^^^^^^^^^^^^^^^^^^^^^^^^^^^^^^^^
[36mbackend_1   |[0m django.db.utils.OperationalError: connection to server at "localhost" (127.0.0.1), port 5432 failed: Connection refused
[36mbackend_1   |[0m 	Is the server running on that host and accepting TCP/IP connections?
[36mbackend_1   |[0m connection to server at "localhost" (::1), port 5432 failed: Cannot assign requested address
[36mbackend_1   |[0m 	Is the server running on that host and accepting TCP/IP connections?
[36mbackend_1   |[0m 
[36mbackend_1   |[0m /usr/local/lib/python3.12/site-packages/django/core/management/commands/makemigrations.py:160: RuntimeWarning: Got an error checking a consistent migration history performed for database connection 'default': connection to server at "localhost" (127.0.0.1), port 5432 failed: Connection refused
[36mbackend_1   |[0m 	Is the server running on that host and accepting TCP/IP connections?
[36mbackend_1   |[0m connection to server at "localhost" (::1), port 5432 failed: Cannot assign requested address
[36mbackend_1   |[0m 	Is the server running on that host and accepting TCP/IP connections?
[36mbackend_1   |[0m 
[36mbackend_1   |[0m   warnings.warn(
[36mbackend_1   |[0m No changes detected
[36mbackend_1   |[0m Traceback (most recent call last):
[36mbackend_1   |[0m   File "/usr/local/lib/python3.12/site-packages/django/db/backends/base/base.py", line 275, in ensure_connection
[36mbackend_1   |[0m     self.connect()
[36mbackend_1   |[0m   File "/usr/local/lib/python3.12/site-packages/django/utils/asyncio.py", line 26, in inner
[36mbackend_1   |[0m     return func(*args, **kwargs)
[36mbackend_1   |[0m            ^^^^^^^^^^^^^^^^^^^^^
[36mbackend_1   |[0m   File "/usr/local/lib/python3.12/site-packages/django/db/backends/base/base.py", line 256, in connect
[36mbackend_1   |[0m     self.connection = self.get_new_connection(conn_params)
[36mbackend_1   |[0m                       ^^^^^^^^^^^^^^^^^^^^^^^^^^^^^^^^^^^^
[36mbackend_1   |[0m   File "/usr/local/lib/python3.12/site-packages/django/utils/asyncio.py", line 26, in inner
[36mbackend_1   |[0m     return func(*args, **kwargs)
[36mbackend_1   |[0m            ^^^^^^^^^^^^^^^^^^^^^
[36mbackend_1   |[0m   File "/usr/local/lib/python3.12/site-packages/django/db/backends/postgresql/base.py", line 277, in get_new_connection
[36mbackend_1   |[0m     connection = self.Database.connect(**conn_params)
[36mbackend_1   |[0m                  ^^^^^^^^^^^^^^^^^^^^^^^^^^^^^^^^^^^^
[36mbackend_1   |[0m   File "/usr/local/lib/python3.12/site-packages/psycopg2/__init__.py", line 122, in connect
[36mbackend_1   |[0m     conn = _connect(dsn, connection_factory=connection_factory, **kwasync)
[36mbackend_1   |[0m            ^^^^^^^^^^^^^^^^^^^^^^^^^^^^^^^^^^^^^^^^^^^^^^^^^^^^^^^^^^^^^^^
[36mbackend_1   |[0m psycopg2.OperationalError: connection to server at "localhost" (127.0.0.1), port 5432 failed: Connection refused
[36mbackend_1   |[0m 	Is the server running on that host and accepting TCP/IP connections?
[36mbackend_1   |[0m connection to server at "localhost" (::1), port 5432 failed: Cannot assign requested address
[36mbackend_1   |[0m 	Is the server running on that host and accepting TCP/IP connections?
[36mbackend_1   |[0m 
[36mbackend_1   |[0m 
[36mbackend_1   |[0m The above exception was the direct cause of the following exception:
[36mbackend_1   |[0m 
[36mbackend_1   |[0m Traceback (most recent call last):
[36mbackend_1   |[0m   File "/app/manage.py", line 22, in <module>
[36mbackend_1   |[0m     main()
[36mbackend_1   |[0m   File "/app/manage.py", line 18, in main
[36mbackend_1   |[0m     execute_from_command_line(sys.argv)
[36mbackend_1   |[0m   File "/usr/local/lib/python3.12/site-packages/django/core/management/__init__.py", line 442, in execute_from_command_line
[36mbackend_1   |[0m     utility.execute()
[36mbackend_1   |[0m   File "/usr/local/lib/python3.12/site-packages/django/core/management/__init__.py", line 436, in execute
[36mbackend_1   |[0m     self.fetch_command(subcommand).run_from_argv(self.argv)
[36mbackend_1   |[0m   File "/usr/local/lib/python3.12/site-packages/django/core/management/base.py", line 413, in run_from_argv
[36mbackend_1   |[0m     self.execute(*args, **cmd_options)
[36mbackend_1   |[0m   File "/usr/local/lib/python3.12/site-packages/django/core/management/base.py", line 459, in execute
[36mbackend_1   |[0m     output = self.handle(*args, **options)
[36mbackend_1   |[0m              ^^^^^^^^^^^^^^^^^^^^^^^^^^^^^
[36mbackend_1   |[0m   File "/usr/local/lib/python3.12/site-packages/django/core/management/base.py", line 107, in wrapper
[36mbackend_1   |[0m     res = handle_func(*args, **kwargs)
[36mbackend_1   |[0m           ^^^^^^^^^^^^^^^^^^^^^^^^^^^^
[36mbackend_1   |[0m   File "/usr/local/lib/python3.12/site-packages/django/core/management/commands/migrate.py", line 100, in handle
[36mbackend_1   |[0m     self.check(databases=[database])
[36mbackend_1   |[0m   File "/usr/local/lib/python3.12/site-packages/django/core/management/base.py", line 486, in check
[36mbackend_1   |[0m     all_issues = checks.run_checks(
[36mbackend_1   |[0m                  ^^^^^^^^^^^^^^^^^^
[36mbackend_1   |[0m   File "/usr/local/lib/python3.12/site-packages/django/core/checks/registry.py", line 88, in run_checks
[36mbackend_1   |[0m     new_errors = check(app_configs=app_configs, databases=databases)
[36mbackend_1   |[0m                  ^^^^^^^^^^^^^^^^^^^^^^^^^^^^^^^^^^^^^^^^^^^^^^^^^^^
[36mbackend_1   |[0m   File "/usr/local/lib/python3.12/site-packages/django/core/checks/model_checks.py", line 36, in check_all_models
[36mbackend_1   |[0m     errors.extend(model.check(**kwargs))
[36mbackend_1   |[0m                   ^^^^^^^^^^^^^^^^^^^^^
[36mbackend_1   |[0m   File "/usr/local/lib/python3.12/site-packages/django/db/models/base.py", line 1610, in check
[36mbackend_1   |[0m     *cls._check_constraints(databases),
[36mbackend_1   |[0m      ^^^^^^^^^^^^^^^^^^^^^^^^^^^^^^^^^
[36mbackend_1   |[0m   File "/usr/local/lib/python3.12/site-packages/django/db/models/base.py", line 2460, in _check_constraints
[36mbackend_1   |[0m     connection.features.supports_nulls_distinct_unique_constraints
[36mbackend_1   |[0m   File "/usr/local/lib/python3.12/site-packages/django/utils/functional.py", line 47, in __get__
[36mbackend_1   |[0m     res = instance.__dict__[self.name] = self.func(instance)
[36mbackend_1   |[0m                                          ^^^^^^^^^^^^^^^^^^^
[36mbackend_1   |[0m   File "/usr/local/lib/python3.12/site-packages/django/db/backends/postgresql/features.py", line 141, in is_postgresql_15
[36mbackend_1   |[0m     return self.connection.pg_version >= 150000
[36mbackend_1   |[0m            ^^^^^^^^^^^^^^^^^^^^^^^^^^
[36mbackend_1   |[0m   File "/usr/local/lib/python3.12/site-packages/django/utils/functional.py", line 47, in __get__
[36mbackend_1   |[0m     res = instance.__dict__[self.name] = self.func(instance)
[36mbackend_1   |[0m                                          ^^^^^^^^^^^^^^^^^^^
[36mbackend_1   |[0m   File "/usr/local/lib/python3.12/site-packages/django/db/backends/postgresql/base.py", line 438, in pg_version
[36mbackend_1   |[0m     with self.temporary_connection():
[36mbackend_1   |[0m   File "/usr/local/lib/python3.12/contextlib.py", line 137, in __enter__
[36mbackend_1   |[0m     return next(self.gen)
[36mbackend_1   |[0m            ^^^^^^^^^^^^^^
[36mbackend_1   |[0m   File "/usr/local/lib/python3.12/site-packages/django/db/backends/base/base.py", line 691, in temporary_connection
[36mbackend_1   |[0m     with self.cursor() as cursor:
[36mbackend_1   |[0m          ^^^^^^^^^^^^^
[36mbackend_1   |[0m   File "/usr/local/lib/python3.12/site-packages/django/utils/asyncio.py", line 26, in inner
[36mbackend_1   |[0m     return func(*args, **kwargs)
[36mbackend_1   |[0m            ^^^^^^^^^^^^^^^^^^^^^
[36mbackend_1   |[0m   File "/usr/local/lib/python3.12/site-packages/django/db/backends/base/base.py", line 316, in cursor
[36mbackend_1   |[0m     return self._cursor()
[36mbackend_1   |[0m            ^^^^^^^^^^^^^^
[36mbackend_1   |[0m   File "/usr/local/lib/python3.12/site-packages/django/db/backends/base/base.py", line 292, in _cursor
[36mbackend_1   |[0m     self.ensure_connection()
[36mbackend_1   |[0m   File "/usr/local/lib/python3.12/site-packages/django/utils/asyncio.py", line 26, in inner
[36mbackend_1   |[0m     return func(*args, **kwargs)
[36mbackend_1   |[0m            ^^^^^^^^^^^^^^^^^^^^^
[36mbackend_1   |[0m   File "/usr/local/lib/python3.12/site-packages/django/db/backends/base/base.py", line 274, in ensure_connection
[36mbackend_1   |[0m     with self.wrap_database_errors:
[36mbackend_1   |[0m   File "/usr/local/lib/python3.12/site-packages/django/db/utils.py", line 91, in __exit__
[36mbackend_1   |[0m     raise dj_exc_value.with_traceback(traceback) from exc_value
[36mbackend_1   |[0m   File "/usr/local/lib/python3.12/site-packages/django/db/backends/base/base.py", line 275, in ensure_connection
[36mbackend_1   |[0m     self.connect()
[36mbackend_1   |[0m   File "/usr/local/lib/python3.12/site-packages/django/utils/asyncio.py", line 26, in inner
[36mbackend_1   |[0m     return func(*args, **kwargs)
[36mbackend_1   |[0m            ^^^^^^^^^^^^^^^^^^^^^
[36mbackend_1   |[0m   File "/usr/local/lib/python3.12/site-packages/django/db/backends/base/base.py", line 256, in connect
[36mbackend_1   |[0m     self.connection = self.get_new_connection(conn_params)
[36mbackend_1   |[0m                       ^^^^^^^^^^^^^^^^^^^^^^^^^^^^^^^^^^^^
[36mbackend_1   |[0m   File "/usr/local/lib/python3.12/site-packages/django/utils/asyncio.py", line 26, in inner
[36mbackend_1   |[0m     return func(*args, **kwargs)
[36mbackend_1   |[0m            ^^^^^^^^^^^^^^^^^^^^^
[36mbackend_1   |[0m   File "/usr/local/lib/python3.12/site-packages/django/db/backends/postgresql/base.py", line 277, in get_new_connection
[36mbackend_1   |[0m     connection = self.Database.connect(**conn_params)
[36mbackend_1   |[0m                  ^^^^^^^^^^^^^^^^^^^^^^^^^^^^^^^^^^^^
[36mbackend_1   |[0m   File "/usr/local/lib/python3.12/site-packages/psycopg2/__init__.py", line 122, in connect
[36mbackend_1   |[0m     conn = _connect(dsn, connection_factory=connection_factory, **kwasync)
[36mbackend_1   |[0m            ^^^^^^^^^^^^^^^^^^^^^^^^^^^^^^^^^^^^^^^^^^^^^^^^^^^^^^^^^^^^^^^
[36mbackend_1   |[0m django.db.utils.OperationalError: connection to server at "localhost" (127.0.0.1), port 5432 failed: Connection refused
[36mbackend_1   |[0m 	Is the server running on that host and accepting TCP/IP connections?
[36mbackend_1   |[0m connection to server at "localhost" (::1), port 5432 failed: Cannot assign requested address
[36mbackend_1   |[0m 	Is the server running on that host and accepting TCP/IP connections?
[36mbackend_1   |[0m 
[36mbackend_1   |[0m /usr/local/lib/python3.12/site-packages/django/core/management/commands/makemigrations.py:160: RuntimeWarning: Got an error checking a consistent migration history performed for database connection 'default': connection to server at "localhost" (127.0.0.1), port 5432 failed: Connection refused
[36mbackend_1   |[0m 	Is the server running on that host and accepting TCP/IP connections?
[36mbackend_1   |[0m connection to server at "localhost" (::1), port 5432 failed: Cannot assign requested address
[36mbackend_1   |[0m 	Is the server running on that host and accepting TCP/IP connections?
[36mbackend_1   |[0m 
[36mbackend_1   |[0m   warnings.warn(
[36mbackend_1   |[0m No changes detected
[36mbackend_1   |[0m Traceback (most recent call last):
[36mbackend_1   |[0m   File "/usr/local/lib/python3.12/site-packages/django/db/backends/base/base.py", line 275, in ensure_connection
[36mbackend_1   |[0m     self.connect()
[36mbackend_1   |[0m   File "/usr/local/lib/python3.12/site-packages/django/utils/asyncio.py", line 26, in inner
[36mbackend_1   |[0m     return func(*args, **kwargs)
[36mbackend_1   |[0m            ^^^^^^^^^^^^^^^^^^^^^
[36mbackend_1   |[0m   File "/usr/local/lib/python3.12/site-packages/django/db/backends/base/base.py", line 256, in connect
[36mbackend_1   |[0m     self.connection = self.get_new_connection(conn_params)
[36mbackend_1   |[0m                       ^^^^^^^^^^^^^^^^^^^^^^^^^^^^^^^^^^^^
[36mbackend_1   |[0m   File "/usr/local/lib/python3.12/site-packages/django/utils/asyncio.py", line 26, in inner
[36mbackend_1   |[0m     return func(*args, **kwargs)
[36mbackend_1   |[0m            ^^^^^^^^^^^^^^^^^^^^^
[36mbackend_1   |[0m   File "/usr/local/lib/python3.12/site-packages/django/db/backends/postgresql/base.py", line 277, in get_new_connection
[36mbackend_1   |[0m     connection = self.Database.connect(**conn_params)
[36mbackend_1   |[0m                  ^^^^^^^^^^^^^^^^^^^^^^^^^^^^^^^^^^^^
[36mbackend_1   |[0m   File "/usr/local/lib/python3.12/site-packages/psycopg2/__init__.py", line 122, in connect
[36mbackend_1   |[0m     conn = _connect(dsn, connection_factory=connection_factory, **kwasync)
[36mbackend_1   |[0m            ^^^^^^^^^^^^^^^^^^^^^^^^^^^^^^^^^^^^^^^^^^^^^^^^^^^^^^^^^^^^^^^
[36mbackend_1   |[0m psycopg2.OperationalError: connection to server at "localhost" (127.0.0.1), port 5432 failed: Connection refused
[36mbackend_1   |[0m 	Is the server running on that host and accepting TCP/IP connections?
[36mbackend_1   |[0m connection to server at "localhost" (::1), port 5432 failed: Cannot assign requested address
[36mbackend_1   |[0m 	Is the server running on that host and accepting TCP/IP connections?
[36mbackend_1   |[0m 
[36mbackend_1   |[0m 
[36mbackend_1   |[0m The above exception was the direct cause of the following exception:
[36mbackend_1   |[0m 
[36mbackend_1   |[0m Traceback (most recent call last):
[36mbackend_1   |[0m   File "/app/manage.py", line 22, in <module>
[36mbackend_1   |[0m     main()
[36mbackend_1   |[0m   File "/app/manage.py", line 18, in main
[36mbackend_1   |[0m     execute_from_command_line(sys.argv)
[36mbackend_1   |[0m   File "/usr/local/lib/python3.12/site-packages/django/core/management/__init__.py", line 442, in execute_from_command_line
[36mbackend_1   |[0m     utility.execute()
[36mbackend_1   |[0m   File "/usr/local/lib/python3.12/site-packages/django/core/management/__init__.py", line 436, in execute
[36mbackend_1   |[0m     self.fetch_command(subcommand).run_from_argv(self.argv)
[36mbackend_1   |[0m   File "/usr/local/lib/python3.12/site-packages/django/core/management/base.py", line 413, in run_from_argv
[36mbackend_1   |[0m     self.execute(*args, **cmd_options)
[36mbackend_1   |[0m   File "/usr/local/lib/python3.12/site-packages/django/core/management/base.py", line 459, in execute
[36mbackend_1   |[0m     output = self.handle(*args, **options)
[36mbackend_1   |[0m              ^^^^^^^^^^^^^^^^^^^^^^^^^^^^^
[36mbackend_1   |[0m   File "/usr/local/lib/python3.12/site-packages/django/core/management/base.py", line 107, in wrapper
[36mbackend_1   |[0m     res = handle_func(*args, **kwargs)
[36mbackend_1   |[0m           ^^^^^^^^^^^^^^^^^^^^^^^^^^^^
[36mbackend_1   |[0m   File "/usr/local/lib/python3.12/site-packages/django/core/management/commands/migrate.py", line 100, in handle
[36mbackend_1   |[0m     self.check(databases=[database])
[36mbackend_1   |[0m   File "/usr/local/lib/python3.12/site-packages/django/core/management/base.py", line 486, in check
[36mbackend_1   |[0m     all_issues = checks.run_checks(
[36mbackend_1   |[0m                  ^^^^^^^^^^^^^^^^^^
[36mbackend_1   |[0m   File "/usr/local/lib/python3.12/site-packages/django/core/checks/registry.py", line 88, in run_checks
[36mbackend_1   |[0m     new_errors = check(app_configs=app_configs, databases=databases)
[36mbackend_1   |[0m                  ^^^^^^^^^^^^^^^^^^^^^^^^^^^^^^^^^^^^^^^^^^^^^^^^^^^
[36mbackend_1   |[0m   File "/usr/local/lib/python3.12/site-packages/django/core/checks/model_checks.py", line 36, in check_all_models
[36mbackend_1   |[0m     errors.extend(model.check(**kwargs))
[36mbackend_1   |[0m                   ^^^^^^^^^^^^^^^^^^^^^
[36mbackend_1   |[0m   File "/usr/local/lib/python3.12/site-packages/django/db/models/base.py", line 1610, in check
[36mbackend_1   |[0m     *cls._check_constraints(databases),
[36mbackend_1   |[0m      ^^^^^^^^^^^^^^^^^^^^^^^^^^^^^^^^^
[36mbackend_1   |[0m   File "/usr/local/lib/python3.12/site-packages/django/db/models/base.py", line 2460, in _check_constraints
[36mbackend_1   |[0m     connection.features.supports_nulls_distinct_unique_constraints
[36mbackend_1   |[0m   File "/usr/local/lib/python3.12/site-packages/django/utils/functional.py", line 47, in __get__
[36mbackend_1   |[0m     res = instance.__dict__[self.name] = self.func(instance)
[36mbackend_1   |[0m                                          ^^^^^^^^^^^^^^^^^^^
[36mbackend_1   |[0m   File "/usr/local/lib/python3.12/site-packages/django/db/backends/postgresql/features.py", line 141, in is_postgresql_15
[36mbackend_1   |[0m     return self.connection.pg_version >= 150000
[36mbackend_1   |[0m            ^^^^^^^^^^^^^^^^^^^^^^^^^^
[36mbackend_1   |[0m   File "/usr/local/lib/python3.12/site-packages/django/utils/functional.py", line 47, in __get__
[36mbackend_1   |[0m     res = instance.__dict__[self.name] = self.func(instance)
[36mbackend_1   |[0m                                          ^^^^^^^^^^^^^^^^^^^
[36mbackend_1   |[0m   File "/usr/local/lib/python3.12/site-packages/django/db/backends/postgresql/base.py", line 438, in pg_version
[36mbackend_1   |[0m     with self.temporary_connection():
[36mbackend_1   |[0m   File "/usr/local/lib/python3.12/contextlib.py", line 137, in __enter__
[36mbackend_1   |[0m     return next(self.gen)
[36mbackend_1   |[0m            ^^^^^^^^^^^^^^
[36mbackend_1   |[0m   File "/usr/local/lib/python3.12/site-packages/django/db/backends/base/base.py", line 691, in temporary_connection
[36mbackend_1   |[0m     with self.cursor() as cursor:
[36mbackend_1   |[0m          ^^^^^^^^^^^^^
[36mbackend_1   |[0m   File "/usr/local/lib/python3.12/site-packages/django/utils/asyncio.py", line 26, in inner
[36mbackend_1   |[0m     return func(*args, **kwargs)
[36mbackend_1   |[0m            ^^^^^^^^^^^^^^^^^^^^^
[36mbackend_1   |[0m   File "/usr/local/lib/python3.12/site-packages/django/db/backends/base/base.py", line 316, in cursor
[36mbackend_1   |[0m     return self._cursor()
[36mbackend_1   |[0m            ^^^^^^^^^^^^^^
[36mbackend_1   |[0m   File "/usr/local/lib/python3.12/site-packages/django/db/backends/base/base.py", line 292, in _cursor
[36mbackend_1   |[0m     self.ensure_connection()
[36mbackend_1   |[0m   File "/usr/local/lib/python3.12/site-packages/django/utils/asyncio.py", line 26, in inner
[36mbackend_1   |[0m     return func(*args, **kwargs)
[36mbackend_1   |[0m            ^^^^^^^^^^^^^^^^^^^^^
[36mbackend_1   |[0m   File "/usr/local/lib/python3.12/site-packages/django/db/backends/base/base.py", line 274, in ensure_connection
[36mbackend_1   |[0m     with self.wrap_database_errors:
[36mbackend_1   |[0m   File "/usr/local/lib/python3.12/site-packages/django/db/utils.py", line 91, in __exit__
[36mbackend_1   |[0m     raise dj_exc_value.with_traceback(traceback) from exc_value
[36mbackend_1   |[0m   File "/usr/local/lib/python3.12/site-packages/django/db/backends/base/base.py", line 275, in ensure_connection
[36mbackend_1   |[0m     self.connect()
[36mbackend_1   |[0m   File "/usr/local/lib/python3.12/site-packages/django/utils/asyncio.py", line 26, in inner
[36mbackend_1   |[0m     return func(*args, **kwargs)
[36mbackend_1   |[0m            ^^^^^^^^^^^^^^^^^^^^^
[36mbackend_1   |[0m   File "/usr/local/lib/python3.12/site-packages/django/db/backends/base/base.py", line 256, in connect
[36mbackend_1   |[0m     self.connection = self.get_new_connection(conn_params)
[36mbackend_1   |[0m                       ^^^^^^^^^^^^^^^^^^^^^^^^^^^^^^^^^^^^
[36mbackend_1   |[0m   File "/usr/local/lib/python3.12/site-packages/django/utils/asyncio.py", line 26, in inner
[36mbackend_1   |[0m     return func(*args, **kwargs)
[36mbackend_1   |[0m            ^^^^^^^^^^^^^^^^^^^^^
[36mbackend_1   |[0m   File "/usr/local/lib/python3.12/site-packages/django/db/backends/postgresql/base.py", line 277, in get_new_connection
[36mbackend_1   |[0m     connection = self.Database.connect(**conn_params)
[36mbackend_1   |[0m                  ^^^^^^^^^^^^^^^^^^^^^^^^^^^^^^^^^^^^
[36mbackend_1   |[0m   File "/usr/local/lib/python3.12/site-packages/psycopg2/__init__.py", line 122, in connect
[36mbackend_1   |[0m     conn = _connect(dsn, connection_factory=connection_factory, **kwasync)
[36mbackend_1   |[0m            ^^^^^^^^^^^^^^^^^^^^^^^^^^^^^^^^^^^^^^^^^^^^^^^^^^^^^^^^^^^^^^^
[36mbackend_1   |[0m django.db.utils.OperationalError: connection to server at "localhost" (127.0.0.1), port 5432 failed: Connection refused
[36mbackend_1   |[0m 	Is the server running on that host and accepting TCP/IP connections?
[36mbackend_1   |[0m connection to server at "localhost" (::1), port 5432 failed: Cannot assign requested address
[36mbackend_1   |[0m 	Is the server running on that host and accepting TCP/IP connections?
[36mbackend_1   |[0m 
[36mbackend_1   |[0m /usr/local/lib/python3.12/site-packages/django/core/management/commands/makemigrations.py:160: RuntimeWarning: Got an error checking a consistent migration history performed for database connection 'default': connection to server at "localhost" (127.0.0.1), port 5432 failed: Connection refused
[36mbackend_1   |[0m 	Is the server running on that host and accepting TCP/IP connections?
[36mbackend_1   |[0m connection to server at "localhost" (::1), port 5432 failed: Cannot assign requested address
[36mbackend_1   |[0m 	Is the server running on that host and accepting TCP/IP connections?
[36mbackend_1   |[0m 
[36mbackend_1   |[0m   warnings.warn(
[36mbackend_1   |[0m No changes detected
[36mbackend_1   |[0m Traceback (most recent call last):
[36mbackend_1   |[0m   File "/usr/local/lib/python3.12/site-packages/django/db/backends/base/base.py", line 275, in ensure_connection
[36mbackend_1   |[0m     self.connect()
[36mbackend_1   |[0m   File "/usr/local/lib/python3.12/site-packages/django/utils/asyncio.py", line 26, in inner
[36mbackend_1   |[0m     return func(*args, **kwargs)
[36mbackend_1   |[0m            ^^^^^^^^^^^^^^^^^^^^^
[36mbackend_1   |[0m   File "/usr/local/lib/python3.12/site-packages/django/db/backends/base/base.py", line 256, in connect
[36mbackend_1   |[0m     self.connection = self.get_new_connection(conn_params)
[36mbackend_1   |[0m                       ^^^^^^^^^^^^^^^^^^^^^^^^^^^^^^^^^^^^
[36mbackend_1   |[0m   File "/usr/local/lib/python3.12/site-packages/django/utils/asyncio.py", line 26, in inner
[36mbackend_1   |[0m     return func(*args, **kwargs)
[36mbackend_1   |[0m            ^^^^^^^^^^^^^^^^^^^^^
[36mbackend_1   |[0m   File "/usr/local/lib/python3.12/site-packages/django/db/backends/postgresql/base.py", line 277, in get_new_connection
[36mbackend_1   |[0m     connection = self.Database.connect(**conn_params)
[36mbackend_1   |[0m                  ^^^^^^^^^^^^^^^^^^^^^^^^^^^^^^^^^^^^
[36mbackend_1   |[0m   File "/usr/local/lib/python3.12/site-packages/psycopg2/__init__.py", line 122, in connect
[36mbackend_1   |[0m     conn = _connect(dsn, connection_factory=connection_factory, **kwasync)
[36mbackend_1   |[0m            ^^^^^^^^^^^^^^^^^^^^^^^^^^^^^^^^^^^^^^^^^^^^^^^^^^^^^^^^^^^^^^^
[36mbackend_1   |[0m psycopg2.OperationalError: connection to server at "localhost" (127.0.0.1), port 5432 failed: Connection refused
[36mbackend_1   |[0m 	Is the server running on that host and accepting TCP/IP connections?
[36mbackend_1   |[0m connection to server at "localhost" (::1), port 5432 failed: Cannot assign requested address
[36mbackend_1   |[0m 	Is the server running on that host and accepting TCP/IP connections?
[36mbackend_1   |[0m 
[36mbackend_1   |[0m 
[36mbackend_1   |[0m The above exception was the direct cause of the following exception:
[36mbackend_1   |[0m 
[36mbackend_1   |[0m Traceback (most recent call last):
[36mbackend_1   |[0m   File "/app/manage.py", line 22, in <module>
[36mbackend_1   |[0m     main()
[36mbackend_1   |[0m   File "/app/manage.py", line 18, in main
[36mbackend_1   |[0m     execute_from_command_line(sys.argv)
[36mbackend_1   |[0m   File "/usr/local/lib/python3.12/site-packages/django/core/management/__init__.py", line 442, in execute_from_command_line
[36mbackend_1   |[0m     utility.execute()
[36mbackend_1   |[0m   File "/usr/local/lib/python3.12/site-packages/django/core/management/__init__.py", line 436, in execute
[36mbackend_1   |[0m     self.fetch_command(subcommand).run_from_argv(self.argv)
[36mbackend_1   |[0m   File "/usr/local/lib/python3.12/site-packages/django/core/management/base.py", line 413, in run_from_argv
[36mbackend_1   |[0m     self.execute(*args, **cmd_options)
[36mbackend_1   |[0m   File "/usr/local/lib/python3.12/site-packages/django/core/management/base.py", line 459, in execute
[36mbackend_1   |[0m     output = self.handle(*args, **options)
[36mbackend_1   |[0m              ^^^^^^^^^^^^^^^^^^^^^^^^^^^^^
[36mbackend_1   |[0m   File "/usr/local/lib/python3.12/site-packages/django/core/management/base.py", line 107, in wrapper
[36mbackend_1   |[0m     res = handle_func(*args, **kwargs)
[36mbackend_1   |[0m           ^^^^^^^^^^^^^^^^^^^^^^^^^^^^
[36mbackend_1   |[0m   File "/usr/local/lib/python3.12/site-packages/django/core/management/commands/migrate.py", line 100, in handle
[36mbackend_1   |[0m     self.check(databases=[database])
[36mbackend_1   |[0m   File "/usr/local/lib/python3.12/site-packages/django/core/management/base.py", line 486, in check
[36mbackend_1   |[0m     all_issues = checks.run_checks(
[36mbackend_1   |[0m                  ^^^^^^^^^^^^^^^^^^
[36mbackend_1   |[0m   File "/usr/local/lib/python3.12/site-packages/django/core/checks/registry.py", line 88, in run_checks
[36mbackend_1   |[0m     new_errors = check(app_configs=app_configs, databases=databases)
[36mbackend_1   |[0m                  ^^^^^^^^^^^^^^^^^^^^^^^^^^^^^^^^^^^^^^^^^^^^^^^^^^^
[36mbackend_1   |[0m   File "/usr/local/lib/python3.12/site-packages/django/core/checks/model_checks.py", line 36, in check_all_models
[36mbackend_1   |[0m     errors.extend(model.check(**kwargs))
[36mbackend_1   |[0m                   ^^^^^^^^^^^^^^^^^^^^^
[36mbackend_1   |[0m   File "/usr/local/lib/python3.12/site-packages/django/db/models/base.py", line 1610, in check
[36mbackend_1   |[0m     *cls._check_constraints(databases),
[36mbackend_1   |[0m      ^^^^^^^^^^^^^^^^^^^^^^^^^^^^^^^^^
[36mbackend_1   |[0m   File "/usr/local/lib/python3.12/site-packages/django/db/models/base.py", line 2460, in _check_constraints
[36mbackend_1   |[0m     connection.features.supports_nulls_distinct_unique_constraints
[36mbackend_1   |[0m   File "/usr/local/lib/python3.12/site-packages/django/utils/functional.py", line 47, in __get__
[36mbackend_1   |[0m     res = instance.__dict__[self.name] = self.func(instance)
[36mbackend_1   |[0m                                          ^^^^^^^^^^^^^^^^^^^
[36mbackend_1   |[0m   File "/usr/local/lib/python3.12/site-packages/django/db/backends/postgresql/features.py", line 141, in is_postgresql_15
[36mbackend_1   |[0m     return self.connection.pg_version >= 150000
[36mbackend_1   |[0m            ^^^^^^^^^^^^^^^^^^^^^^^^^^
[36mbackend_1   |[0m   File "/usr/local/lib/python3.12/site-packages/django/utils/functional.py", line 47, in __get__
[36mbackend_1   |[0m     res = instance.__dict__[self.name] = self.func(instance)
[36mbackend_1   |[0m                                          ^^^^^^^^^^^^^^^^^^^
[36mbackend_1   |[0m   File "/usr/local/lib/python3.12/site-packages/django/db/backends/postgresql/base.py", line 438, in pg_version
[36mbackend_1   |[0m     with self.temporary_connection():
[36mbackend_1   |[0m   File "/usr/local/lib/python3.12/contextlib.py", line 137, in __enter__
[36mbackend_1   |[0m     return next(self.gen)
[36mbackend_1   |[0m            ^^^^^^^^^^^^^^
[36mbackend_1   |[0m   File "/usr/local/lib/python3.12/site-packages/django/db/backends/base/base.py", line 691, in temporary_connection
[36mbackend_1   |[0m     with self.cursor() as cursor:
[36mbackend_1   |[0m          ^^^^^^^^^^^^^
[36mbackend_1   |[0m   File "/usr/local/lib/python3.12/site-packages/django/utils/asyncio.py", line 26, in inner
[36mbackend_1   |[0m     return func(*args, **kwargs)
[36mbackend_1   |[0m            ^^^^^^^^^^^^^^^^^^^^^
[36mbackend_1   |[0m   File "/usr/local/lib/python3.12/site-packages/django/db/backends/base/base.py", line 316, in cursor
[36mbackend_1   |[0m     return self._cursor()
[36mbackend_1   |[0m            ^^^^^^^^^^^^^^
[36mbackend_1   |[0m   File "/usr/local/lib/python3.12/site-packages/django/db/backends/base/base.py", line 292, in _cursor
[36mbackend_1   |[0m     self.ensure_connection()
[36mbackend_1   |[0m   File "/usr/local/lib/python3.12/site-packages/django/utils/asyncio.py", line 26, in inner
[36mbackend_1   |[0m     return func(*args, **kwargs)
[36mbackend_1   |[0m            ^^^^^^^^^^^^^^^^^^^^^
[36mbackend_1   |[0m   File "/usr/local/lib/python3.12/site-packages/django/db/backends/base/base.py", line 274, in ensure_connection
[36mbackend_1   |[0m     with self.wrap_database_errors:
[36mbackend_1   |[0m   File "/usr/local/lib/python3.12/site-packages/django/db/utils.py", line 91, in __exit__
[36mbackend_1   |[0m     raise dj_exc_value.with_traceback(traceback) from exc_value
[36mbackend_1   |[0m   File "/usr/local/lib/python3.12/site-packages/django/db/backends/base/base.py", line 275, in ensure_connection
[36mbackend_1   |[0m     self.connect()
[36mbackend_1   |[0m   File "/usr/local/lib/python3.12/site-packages/django/utils/asyncio.py", line 26, in inner
[36mbackend_1   |[0m     return func(*args, **kwargs)
[36mbackend_1   |[0m            ^^^^^^^^^^^^^^^^^^^^^
[36mbackend_1   |[0m   File "/usr/local/lib/python3.12/site-packages/django/db/backends/base/base.py", line 256, in connect
[36mbackend_1   |[0m     self.connection = self.get_new_connection(conn_params)
[36mbackend_1   |[0m                       ^^^^^^^^^^^^^^^^^^^^^^^^^^^^^^^^^^^^
[36mbackend_1   |[0m   File "/usr/local/lib/python3.12/site-packages/django/utils/asyncio.py", line 26, in inner
[36mbackend_1   |[0m     return func(*args, **kwargs)
[36mbackend_1   |[0m            ^^^^^^^^^^^^^^^^^^^^^
[36mbackend_1   |[0m   File "/usr/local/lib/python3.12/site-packages/django/db/backends/postgresql/base.py", line 277, in get_new_connection
[36mbackend_1   |[0m     connection = self.Database.connect(**conn_params)
[36mbackend_1   |[0m                  ^^^^^^^^^^^^^^^^^^^^^^^^^^^^^^^^^^^^
[36mbackend_1   |[0m   File "/usr/local/lib/python3.12/site-packages/psycopg2/__init__.py", line 122, in connect
[36mbackend_1   |[0m     conn = _connect(dsn, connection_factory=connection_factory, **kwasync)
[36mbackend_1   |[0m            ^^^^^^^^^^^^^^^^^^^^^^^^^^^^^^^^^^^^^^^^^^^^^^^^^^^^^^^^^^^^^^^
[36mbackend_1   |[0m django.db.utils.OperationalError: connection to server at "localhost" (127.0.0.1), port 5432 failed: Connection refused
[36mbackend_1   |[0m 	Is the server running on that host and accepting TCP/IP connections?
[36mbackend_1   |[0m connection to server at "localhost" (::1), port 5432 failed: Cannot assign requested address
[36mbackend_1   |[0m 	Is the server running on that host and accepting TCP/IP connections?
[36mbackend_1   |[0m 
[36mbackend_1   |[0m /usr/local/lib/python3.12/site-packages/django/core/management/commands/makemigrations.py:160: RuntimeWarning: Got an error checking a consistent migration history performed for database connection 'default': connection to server at "localhost" (127.0.0.1), port 5432 failed: Connection refused
[36mbackend_1   |[0m 	Is the server running on that host and accepting TCP/IP connections?
[36mbackend_1   |[0m connection to server at "localhost" (::1), port 5432 failed: Cannot assign requested address
[36mbackend_1   |[0m 	Is the server running on that host and accepting TCP/IP connections?
[36mbackend_1   |[0m 
[36mbackend_1   |[0m   warnings.warn(
[36mbackend_1   |[0m No changes detected
[36mbackend_1   |[0m Traceback (most recent call last):
[36mbackend_1   |[0m   File "/usr/local/lib/python3.12/site-packages/django/db/backends/base/base.py", line 275, in ensure_connection
[36mbackend_1   |[0m     self.connect()
[36mbackend_1   |[0m   File "/usr/local/lib/python3.12/site-packages/django/utils/asyncio.py", line 26, in inner
[36mbackend_1   |[0m     return func(*args, **kwargs)
[36mbackend_1   |[0m            ^^^^^^^^^^^^^^^^^^^^^
[36mbackend_1   |[0m   File "/usr/local/lib/python3.12/site-packages/django/db/backends/base/base.py", line 256, in connect
[36mbackend_1   |[0m     self.connection = self.get_new_connection(conn_params)
[36mbackend_1   |[0m                       ^^^^^^^^^^^^^^^^^^^^^^^^^^^^^^^^^^^^
[36mbackend_1   |[0m   File "/usr/local/lib/python3.12/site-packages/django/utils/asyncio.py", line 26, in inner
[36mbackend_1   |[0m     return func(*args, **kwargs)
[36mbackend_1   |[0m            ^^^^^^^^^^^^^^^^^^^^^
[36mbackend_1   |[0m   File "/usr/local/lib/python3.12/site-packages/django/db/backends/postgresql/base.py", line 277, in get_new_connection
[36mbackend_1   |[0m     connection = self.Database.connect(**conn_params)
[36mbackend_1   |[0m                  ^^^^^^^^^^^^^^^^^^^^^^^^^^^^^^^^^^^^
[36mbackend_1   |[0m   File "/usr/local/lib/python3.12/site-packages/psycopg2/__init__.py", line 122, in connect
[36mbackend_1   |[0m     conn = _connect(dsn, connection_factory=connection_factory, **kwasync)
[36mbackend_1   |[0m            ^^^^^^^^^^^^^^^^^^^^^^^^^^^^^^^^^^^^^^^^^^^^^^^^^^^^^^^^^^^^^^^
[36mbackend_1   |[0m psycopg2.OperationalError: connection to server at "localhost" (127.0.0.1), port 5432 failed: Connection refused
[36mbackend_1   |[0m 	Is the server running on that host and accepting TCP/IP connections?
[36mbackend_1   |[0m connection to server at "localhost" (::1), port 5432 failed: Cannot assign requested address
[36mbackend_1   |[0m 	Is the server running on that host and accepting TCP/IP connections?
[36mbackend_1   |[0m 
[36mbackend_1   |[0m 
[36mbackend_1   |[0m The above exception was the direct cause of the following exception:
[36mbackend_1   |[0m 
[36mbackend_1   |[0m Traceback (most recent call last):
[36mbackend_1   |[0m   File "/app/manage.py", line 22, in <module>
[36mbackend_1   |[0m     main()
[36mbackend_1   |[0m   File "/app/manage.py", line 18, in main
[36mbackend_1   |[0m     execute_from_command_line(sys.argv)
[36mbackend_1   |[0m   File "/usr/local/lib/python3.12/site-packages/django/core/management/__init__.py", line 442, in execute_from_command_line
[36mbackend_1   |[0m     utility.execute()
[36mbackend_1   |[0m   File "/usr/local/lib/python3.12/site-packages/django/core/management/__init__.py", line 436, in execute
[36mbackend_1   |[0m     self.fetch_command(subcommand).run_from_argv(self.argv)
[36mbackend_1   |[0m   File "/usr/local/lib/python3.12/site-packages/django/core/management/base.py", line 413, in run_from_argv
[36mbackend_1   |[0m     self.execute(*args, **cmd_options)
[36mbackend_1   |[0m   File "/usr/local/lib/python3.12/site-packages/django/core/management/base.py", line 459, in execute
[36mbackend_1   |[0m     output = self.handle(*args, **options)
[36mbackend_1   |[0m              ^^^^^^^^^^^^^^^^^^^^^^^^^^^^^
[36mbackend_1   |[0m   File "/usr/local/lib/python3.12/site-packages/django/core/management/base.py", line 107, in wrapper
[36mbackend_1   |[0m     res = handle_func(*args, **kwargs)
[36mbackend_1   |[0m           ^^^^^^^^^^^^^^^^^^^^^^^^^^^^
[36mbackend_1   |[0m   File "/usr/local/lib/python3.12/site-packages/django/core/management/commands/migrate.py", line 100, in handle
[36mbackend_1   |[0m     self.check(databases=[database])
[36mbackend_1   |[0m   File "/usr/local/lib/python3.12/site-packages/django/core/management/base.py", line 486, in check
[36mbackend_1   |[0m     all_issues = checks.run_checks(
[36mbackend_1   |[0m                  ^^^^^^^^^^^^^^^^^^
[36mbackend_1   |[0m   File "/usr/local/lib/python3.12/site-packages/django/core/checks/registry.py", line 88, in run_checks
[36mbackend_1   |[0m     new_errors = check(app_configs=app_configs, databases=databases)
[36mbackend_1   |[0m                  ^^^^^^^^^^^^^^^^^^^^^^^^^^^^^^^^^^^^^^^^^^^^^^^^^^^
[36mbackend_1   |[0m   File "/usr/local/lib/python3.12/site-packages/django/core/checks/model_checks.py", line 36, in check_all_models
[36mbackend_1   |[0m     errors.extend(model.check(**kwargs))
[36mbackend_1   |[0m                   ^^^^^^^^^^^^^^^^^^^^^
[36mbackend_1   |[0m   File "/usr/local/lib/python3.12/site-packages/django/db/models/base.py", line 1610, in check
[36mbackend_1   |[0m     *cls._check_constraints(databases),
[36mbackend_1   |[0m      ^^^^^^^^^^^^^^^^^^^^^^^^^^^^^^^^^
[36mbackend_1   |[0m   File "/usr/local/lib/python3.12/site-packages/django/db/models/base.py", line 2460, in _check_constraints
[36mbackend_1   |[0m     connection.features.supports_nulls_distinct_unique_constraints
[36mbackend_1   |[0m   File "/usr/local/lib/python3.12/site-packages/django/utils/functional.py", line 47, in __get__
[36mbackend_1   |[0m     res = instance.__dict__[self.name] = self.func(instance)
[36mbackend_1   |[0m                                          ^^^^^^^^^^^^^^^^^^^
[36mbackend_1   |[0m   File "/usr/local/lib/python3.12/site-packages/django/db/backends/postgresql/features.py", line 141, in is_postgresql_15
[36mbackend_1   |[0m     return self.connection.pg_version >= 150000
[36mbackend_1   |[0m            ^^^^^^^^^^^^^^^^^^^^^^^^^^
[36mbackend_1   |[0m   File "/usr/local/lib/python3.12/site-packages/django/utils/functional.py", line 47, in __get__
[36mbackend_1   |[0m     res = instance.__dict__[self.name] = self.func(instance)
[36mbackend_1   |[0m                                          ^^^^^^^^^^^^^^^^^^^
[36mbackend_1   |[0m   File "/usr/local/lib/python3.12/site-packages/django/db/backends/postgresql/base.py", line 438, in pg_version
[36mbackend_1   |[0m     with self.temporary_connection():
[36mbackend_1   |[0m   File "/usr/local/lib/python3.12/contextlib.py", line 137, in __enter__
[36mbackend_1   |[0m     return next(self.gen)
[36mbackend_1   |[0m            ^^^^^^^^^^^^^^
[36mbackend_1   |[0m   File "/usr/local/lib/python3.12/site-packages/django/db/backends/base/base.py", line 691, in temporary_connection
[36mbackend_1   |[0m     with self.cursor() as cursor:
[36mbackend_1   |[0m          ^^^^^^^^^^^^^
[36mbackend_1   |[0m   File "/usr/local/lib/python3.12/site-packages/django/utils/asyncio.py", line 26, in inner
[36mbackend_1   |[0m     return func(*args, **kwargs)
[36mbackend_1   |[0m            ^^^^^^^^^^^^^^^^^^^^^
[36mbackend_1   |[0m   File "/usr/local/lib/python3.12/site-packages/django/db/backends/base/base.py", line 316, in cursor
[36mbackend_1   |[0m     return self._cursor()
[36mbackend_1   |[0m            ^^^^^^^^^^^^^^
[36mbackend_1   |[0m   File "/usr/local/lib/python3.12/site-packages/django/db/backends/base/base.py", line 292, in _cursor
[36mbackend_1   |[0m     self.ensure_connection()
[36mbackend_1   |[0m   File "/usr/local/lib/python3.12/site-packages/django/utils/asyncio.py", line 26, in inner
[36mbackend_1   |[0m     return func(*args, **kwargs)
[36mbackend_1   |[0m            ^^^^^^^^^^^^^^^^^^^^^
[36mbackend_1   |[0m   File "/usr/local/lib/python3.12/site-packages/django/db/backends/base/base.py", line 274, in ensure_connection
[36mbackend_1   |[0m     with self.wrap_database_errors:
[36mbackend_1   |[0m   File "/usr/local/lib/python3.12/site-packages/django/db/utils.py", line 91, in __exit__
[36mbackend_1   |[0m     raise dj_exc_value.with_traceback(traceback) from exc_value
[36mbackend_1   |[0m   File "/usr/local/lib/python3.12/site-packages/django/db/backends/base/base.py", line 275, in ensure_connection
[36mbackend_1   |[0m     self.connect()
[36mbackend_1   |[0m   File "/usr/local/lib/python3.12/site-packages/django/utils/asyncio.py", line 26, in inner
[36mbackend_1   |[0m     return func(*args, **kwargs)
[36mbackend_1   |[0m            ^^^^^^^^^^^^^^^^^^^^^
[36mbackend_1   |[0m   File "/usr/local/lib/python3.12/site-packages/django/db/backends/base/base.py", line 256, in connect
[36mbackend_1   |[0m     self.connection = self.get_new_connection(conn_params)
[36mbackend_1   |[0m                       ^^^^^^^^^^^^^^^^^^^^^^^^^^^^^^^^^^^^
[36mbackend_1   |[0m   File "/usr/local/lib/python3.12/site-packages/django/utils/asyncio.py", line 26, in inner
[36mbackend_1   |[0m     return func(*args, **kwargs)
[36mbackend_1   |[0m            ^^^^^^^^^^^^^^^^^^^^^
[36mbackend_1   |[0m   File "/usr/local/lib/python3.12/site-packages/django/db/backends/postgresql/base.py", line 277, in get_new_connection
[36mbackend_1   |[0m     connection = self.Database.connect(**conn_params)
[36mbackend_1   |[0m                  ^^^^^^^^^^^^^^^^^^^^^^^^^^^^^^^^^^^^
[36mbackend_1   |[0m   File "/usr/local/lib/python3.12/site-packages/psycopg2/__init__.py", line 122, in connect
[36mbackend_1   |[0m     conn = _connect(dsn, connection_factory=connection_factory, **kwasync)
[36mbackend_1   |[0m            ^^^^^^^^^^^^^^^^^^^^^^^^^^^^^^^^^^^^^^^^^^^^^^^^^^^^^^^^^^^^^^^
[36mbackend_1   |[0m django.db.utils.OperationalError: connection to server at "localhost" (127.0.0.1), port 5432 failed: Connection refused
[36mbackend_1   |[0m 	Is the server running on that host and accepting TCP/IP connections?
[36mbackend_1   |[0m connection to server at "localhost" (::1), port 5432 failed: Cannot assign requested address
[36mbackend_1   |[0m 	Is the server running on that host and accepting TCP/IP connections?
[36mbackend_1   |[0m 
[36mbackend_1   |[0m /usr/local/lib/python3.12/site-packages/django/core/management/commands/makemigrations.py:160: RuntimeWarning: Got an error checking a consistent migration history performed for database connection 'default': connection to server at "localhost" (127.0.0.1), port 5432 failed: Connection refused
[36mbackend_1   |[0m 	Is the server running on that host and accepting TCP/IP connections?
[36mbackend_1   |[0m connection to server at "localhost" (::1), port 5432 failed: Cannot assign requested address
[36mbackend_1   |[0m 	Is the server running on that host and accepting TCP/IP connections?
[36mbackend_1   |[0m 
[36mbackend_1   |[0m   warnings.warn(
[36mbackend_1   |[0m No changes detected
[36mbackend_1   |[0m Traceback (most recent call last):
[36mbackend_1   |[0m   File "/usr/local/lib/python3.12/site-packages/django/db/backends/base/base.py", line 275, in ensure_connection
[36mbackend_1   |[0m     self.connect()
[36mbackend_1   |[0m   File "/usr/local/lib/python3.12/site-packages/django/utils/asyncio.py", line 26, in inner
[36mbackend_1   |[0m     return func(*args, **kwargs)
[36mbackend_1   |[0m            ^^^^^^^^^^^^^^^^^^^^^
[36mbackend_1   |[0m   File "/usr/local/lib/python3.12/site-packages/django/db/backends/base/base.py", line 256, in connect
[36mbackend_1   |[0m     self.connection = self.get_new_connection(conn_params)
[36mbackend_1   |[0m                       ^^^^^^^^^^^^^^^^^^^^^^^^^^^^^^^^^^^^
[36mbackend_1   |[0m   File "/usr/local/lib/python3.12/site-packages/django/utils/asyncio.py", line 26, in inner
[36mbackend_1   |[0m     return func(*args, **kwargs)
[36mbackend_1   |[0m            ^^^^^^^^^^^^^^^^^^^^^
[36mbackend_1   |[0m   File "/usr/local/lib/python3.12/site-packages/django/db/backends/postgresql/base.py", line 277, in get_new_connection
[36mbackend_1   |[0m     connection = self.Database.connect(**conn_params)
[36mbackend_1   |[0m                  ^^^^^^^^^^^^^^^^^^^^^^^^^^^^^^^^^^^^
[36mbackend_1   |[0m   File "/usr/local/lib/python3.12/site-packages/psycopg2/__init__.py", line 122, in connect
[36mbackend_1   |[0m     conn = _connect(dsn, connection_factory=connection_factory, **kwasync)
[36mbackend_1   |[0m            ^^^^^^^^^^^^^^^^^^^^^^^^^^^^^^^^^^^^^^^^^^^^^^^^^^^^^^^^^^^^^^^
[36mbackend_1   |[0m psycopg2.OperationalError: connection to server at "localhost" (127.0.0.1), port 5432 failed: Connection refused
[36mbackend_1   |[0m 	Is the server running on that host and accepting TCP/IP connections?
[36mbackend_1   |[0m connection to server at "localhost" (::1), port 5432 failed: Cannot assign requested address
[36mbackend_1   |[0m 	Is the server running on that host and accepting TCP/IP connections?
[36mbackend_1   |[0m 
[36mbackend_1   |[0m 
[36mbackend_1   |[0m The above exception was the direct cause of the following exception:
[36mbackend_1   |[0m 
[36mbackend_1   |[0m Traceback (most recent call last):
[36mbackend_1   |[0m   File "/app/manage.py", line 22, in <module>
[36mbackend_1   |[0m     main()
[36mbackend_1   |[0m   File "/app/manage.py", line 18, in main
[36mbackend_1   |[0m     execute_from_command_line(sys.argv)
[36mbackend_1   |[0m   File "/usr/local/lib/python3.12/site-packages/django/core/management/__init__.py", line 442, in execute_from_command_line
[36mbackend_1   |[0m     utility.execute()
[36mbackend_1   |[0m   File "/usr/local/lib/python3.12/site-packages/django/core/management/__init__.py", line 436, in execute
[36mbackend_1   |[0m     self.fetch_command(subcommand).run_from_argv(self.argv)
[36mbackend_1   |[0m   File "/usr/local/lib/python3.12/site-packages/django/core/management/base.py", line 413, in run_from_argv
[36mbackend_1   |[0m     self.execute(*args, **cmd_options)
[36mbackend_1   |[0m   File "/usr/local/lib/python3.12/site-packages/django/core/management/base.py", line 459, in execute
[36mbackend_1   |[0m     output = self.handle(*args, **options)
[36mbackend_1   |[0m              ^^^^^^^^^^^^^^^^^^^^^^^^^^^^^
[36mbackend_1   |[0m   File "/usr/local/lib/python3.12/site-packages/django/core/management/base.py", line 107, in wrapper
[36mbackend_1   |[0m     res = handle_func(*args, **kwargs)
[36mbackend_1   |[0m           ^^^^^^^^^^^^^^^^^^^^^^^^^^^^
[36mbackend_1   |[0m   File "/usr/local/lib/python3.12/site-packages/django/core/management/commands/migrate.py", line 100, in handle
[36mbackend_1   |[0m     self.check(databases=[database])
[36mbackend_1   |[0m   File "/usr/local/lib/python3.12/site-packages/django/core/management/base.py", line 486, in check
[36mbackend_1   |[0m     all_issues = checks.run_checks(
[36mbackend_1   |[0m                  ^^^^^^^^^^^^^^^^^^
[36mbackend_1   |[0m   File "/usr/local/lib/python3.12/site-packages/django/core/checks/registry.py", line 88, in run_checks
[36mbackend_1   |[0m     new_errors = check(app_configs=app_configs, databases=databases)
[36mbackend_1   |[0m                  ^^^^^^^^^^^^^^^^^^^^^^^^^^^^^^^^^^^^^^^^^^^^^^^^^^^
[36mbackend_1   |[0m   File "/usr/local/lib/python3.12/site-packages/django/core/checks/model_checks.py", line 36, in check_all_models
[36mbackend_1   |[0m     errors.extend(model.check(**kwargs))
[36mbackend_1   |[0m                   ^^^^^^^^^^^^^^^^^^^^^
[36mbackend_1   |[0m   File "/usr/local/lib/python3.12/site-packages/django/db/models/base.py", line 1610, in check
[36mbackend_1   |[0m     *cls._check_constraints(databases),
[36mbackend_1   |[0m      ^^^^^^^^^^^^^^^^^^^^^^^^^^^^^^^^^
[36mbackend_1   |[0m   File "/usr/local/lib/python3.12/site-packages/django/db/models/base.py", line 2460, in _check_constraints
[36mbackend_1   |[0m     connection.features.supports_nulls_distinct_unique_constraints
[36mbackend_1   |[0m   File "/usr/local/lib/python3.12/site-packages/django/utils/functional.py", line 47, in __get__
[36mbackend_1   |[0m     res = instance.__dict__[self.name] = self.func(instance)
[36mbackend_1   |[0m                                          ^^^^^^^^^^^^^^^^^^^
[36mbackend_1   |[0m   File "/usr/local/lib/python3.12/site-packages/django/db/backends/postgresql/features.py", line 141, in is_postgresql_15
[36mbackend_1   |[0m     return self.connection.pg_version >= 150000
[36mbackend_1   |[0m            ^^^^^^^^^^^^^^^^^^^^^^^^^^
[36mbackend_1   |[0m   File "/usr/local/lib/python3.12/site-packages/django/utils/functional.py", line 47, in __get__
[36mbackend_1   |[0m     res = instance.__dict__[self.name] = self.func(instance)
[36mbackend_1   |[0m                                          ^^^^^^^^^^^^^^^^^^^
[36mbackend_1   |[0m   File "/usr/local/lib/python3.12/site-packages/django/db/backends/postgresql/base.py", line 438, in pg_version
[36mbackend_1   |[0m     with self.temporary_connection():
[36mbackend_1   |[0m   File "/usr/local/lib/python3.12/contextlib.py", line 137, in __enter__
[36mbackend_1   |[0m     return next(self.gen)
[36mbackend_1   |[0m            ^^^^^^^^^^^^^^
[36mbackend_1   |[0m   File "/usr/local/lib/python3.12/site-packages/django/db/backends/base/base.py", line 691, in temporary_connection
[36mbackend_1   |[0m     with self.cursor() as cursor:
[36mbackend_1   |[0m          ^^^^^^^^^^^^^
[36mbackend_1   |[0m   File "/usr/local/lib/python3.12/site-packages/django/utils/asyncio.py", line 26, in inner
[36mbackend_1   |[0m     return func(*args, **kwargs)
[36mbackend_1   |[0m            ^^^^^^^^^^^^^^^^^^^^^
[36mbackend_1   |[0m   File "/usr/local/lib/python3.12/site-packages/django/db/backends/base/base.py", line 316, in cursor
[36mbackend_1   |[0m     return self._cursor()
[36mbackend_1   |[0m            ^^^^^^^^^^^^^^
[36mbackend_1   |[0m   File "/usr/local/lib/python3.12/site-packages/django/db/backends/base/base.py", line 292, in _cursor
[36mbackend_1   |[0m     self.ensure_connection()
[36mbackend_1   |[0m   File "/usr/local/lib/python3.12/site-packages/django/utils/asyncio.py", line 26, in inner
[36mbackend_1   |[0m     return func(*args, **kwargs)
[36mbackend_1   |[0m            ^^^^^^^^^^^^^^^^^^^^^
[36mbackend_1   |[0m   File "/usr/local/lib/python3.12/site-packages/django/db/backends/base/base.py", line 274, in ensure_connection
[36mbackend_1   |[0m     with self.wrap_database_errors:
[36mbackend_1   |[0m   File "/usr/local/lib/python3.12/site-packages/django/db/utils.py", line 91, in __exit__
[36mbackend_1   |[0m     raise dj_exc_value.with_traceback(traceback) from exc_value
[36mbackend_1   |[0m   File "/usr/local/lib/python3.12/site-packages/django/db/backends/base/base.py", line 275, in ensure_connection
[36mbackend_1   |[0m     self.connect()
[36mbackend_1   |[0m   File "/usr/local/lib/python3.12/site-packages/django/utils/asyncio.py", line 26, in inner
[36mbackend_1   |[0m     return func(*args, **kwargs)
[36mbackend_1   |[0m            ^^^^^^^^^^^^^^^^^^^^^
[36mbackend_1   |[0m   File "/usr/local/lib/python3.12/site-packages/django/db/backends/base/base.py", line 256, in connect
[36mbackend_1   |[0m     self.connection = self.get_new_connection(conn_params)
[36mbackend_1   |[0m                       ^^^^^^^^^^^^^^^^^^^^^^^^^^^^^^^^^^^^
[36mbackend_1   |[0m   File "/usr/local/lib/python3.12/site-packages/django/utils/asyncio.py", line 26, in inner
[36mbackend_1   |[0m     return func(*args, **kwargs)
[36mbackend_1   |[0m            ^^^^^^^^^^^^^^^^^^^^^
[36mbackend_1   |[0m   File "/usr/local/lib/python3.12/site-packages/django/db/backends/postgresql/base.py", line 277, in get_new_connection
[36mbackend_1   |[0m     connection = self.Database.connect(**conn_params)
[36mbackend_1   |[0m                  ^^^^^^^^^^^^^^^^^^^^^^^^^^^^^^^^^^^^
[36mbackend_1   |[0m   File "/usr/local/lib/python3.12/site-packages/psycopg2/__init__.py", line 122, in connect
[36mbackend_1   |[0m     conn = _connect(dsn, connection_factory=connection_factory, **kwasync)
[36mbackend_1   |[0m            ^^^^^^^^^^^^^^^^^^^^^^^^^^^^^^^^^^^^^^^^^^^^^^^^^^^^^^^^^^^^^^^
[36mbackend_1   |[0m django.db.utils.OperationalError: connection to server at "localhost" (127.0.0.1), port 5432 failed: Connection refused
[36mbackend_1   |[0m 	Is the server running on that host and accepting TCP/IP connections?
[36mbackend_1   |[0m connection to server at "localhost" (::1), port 5432 failed: Cannot assign requested address
[36mbackend_1   |[0m 	Is the server running on that host and accepting TCP/IP connections?
[36mbackend_1   |[0m 
[36mbackend_1   |[0m /usr/local/lib/python3.12/site-packages/django/core/management/commands/makemigrations.py:160: RuntimeWarning: Got an error checking a consistent migration history performed for database connection 'default': connection to server at "localhost" (127.0.0.1), port 5432 failed: Connection refused
[36mbackend_1   |[0m 	Is the server running on that host and accepting TCP/IP connections?
[36mbackend_1   |[0m connection to server at "localhost" (::1), port 5432 failed: Cannot assign requested address
[36mbackend_1   |[0m 	Is the server running on that host and accepting TCP/IP connections?
[36mbackend_1   |[0m 
[36mbackend_1   |[0m   warnings.warn(
[36mbackend_1   |[0m No changes detected
[36mbackend_1   |[0m Traceback (most recent call last):
[36mbackend_1   |[0m   File "/usr/local/lib/python3.12/site-packages/django/db/backends/base/base.py", line 275, in ensure_connection
[36mbackend_1   |[0m     self.connect()
[36mbackend_1   |[0m   File "/usr/local/lib/python3.12/site-packages/django/utils/asyncio.py", line 26, in inner
[36mbackend_1   |[0m     return func(*args, **kwargs)
[36mbackend_1   |[0m            ^^^^^^^^^^^^^^^^^^^^^
[36mbackend_1   |[0m   File "/usr/local/lib/python3.12/site-packages/django/db/backends/base/base.py", line 256, in connect
[36mbackend_1   |[0m     self.connection = self.get_new_connection(conn_params)
[36mbackend_1   |[0m                       ^^^^^^^^^^^^^^^^^^^^^^^^^^^^^^^^^^^^
[36mbackend_1   |[0m   File "/usr/local/lib/python3.12/site-packages/django/utils/asyncio.py", line 26, in inner
[36mbackend_1   |[0m     return func(*args, **kwargs)
[36mbackend_1   |[0m            ^^^^^^^^^^^^^^^^^^^^^
[36mbackend_1   |[0m   File "/usr/local/lib/python3.12/site-packages/django/db/backends/postgresql/base.py", line 277, in get_new_connection
[36mbackend_1   |[0m     connection = self.Database.connect(**conn_params)
[36mbackend_1   |[0m                  ^^^^^^^^^^^^^^^^^^^^^^^^^^^^^^^^^^^^
[36mbackend_1   |[0m   File "/usr/local/lib/python3.12/site-packages/psycopg2/__init__.py", line 122, in connect
[36mbackend_1   |[0m     conn = _connect(dsn, connection_factory=connection_factory, **kwasync)
[36mbackend_1   |[0m            ^^^^^^^^^^^^^^^^^^^^^^^^^^^^^^^^^^^^^^^^^^^^^^^^^^^^^^^^^^^^^^^
[36mbackend_1   |[0m psycopg2.OperationalError: connection to server at "localhost" (127.0.0.1), port 5432 failed: Connection refused
[36mbackend_1   |[0m 	Is the server running on that host and accepting TCP/IP connections?
[36mbackend_1   |[0m connection to server at "localhost" (::1), port 5432 failed: Cannot assign requested address
[36mbackend_1   |[0m 	Is the server running on that host and accepting TCP/IP connections?
[36mbackend_1   |[0m 
[36mbackend_1   |[0m 
[36mbackend_1   |[0m The above exception was the direct cause of the following exception:
[36mbackend_1   |[0m 
[36mbackend_1   |[0m Traceback (most recent call last):
[36mbackend_1   |[0m   File "/app/manage.py", line 22, in <module>
[36mbackend_1   |[0m     main()
[36mbackend_1   |[0m   File "/app/manage.py", line 18, in main
[36mbackend_1   |[0m     execute_from_command_line(sys.argv)
[36mbackend_1   |[0m   File "/usr/local/lib/python3.12/site-packages/django/core/management/__init__.py", line 442, in execute_from_command_line
[36mbackend_1   |[0m     utility.execute()
[36mbackend_1   |[0m   File "/usr/local/lib/python3.12/site-packages/django/core/management/__init__.py", line 436, in execute
[36mbackend_1   |[0m     self.fetch_command(subcommand).run_from_argv(self.argv)
[36mbackend_1   |[0m   File "/usr/local/lib/python3.12/site-packages/django/core/management/base.py", line 413, in run_from_argv
[36mbackend_1   |[0m     self.execute(*args, **cmd_options)
[36mbackend_1   |[0m   File "/usr/local/lib/python3.12/site-packages/django/core/management/base.py", line 459, in execute
[36mbackend_1   |[0m     output = self.handle(*args, **options)
[36mbackend_1   |[0m              ^^^^^^^^^^^^^^^^^^^^^^^^^^^^^
[36mbackend_1   |[0m   File "/usr/local/lib/python3.12/site-packages/django/core/management/base.py", line 107, in wrapper
[36mbackend_1   |[0m     res = handle_func(*args, **kwargs)
[36mbackend_1   |[0m           ^^^^^^^^^^^^^^^^^^^^^^^^^^^^
[36mbackend_1   |[0m   File "/usr/local/lib/python3.12/site-packages/django/core/management/commands/migrate.py", line 100, in handle
[36mbackend_1   |[0m     self.check(databases=[database])
[36mbackend_1   |[0m   File "/usr/local/lib/python3.12/site-packages/django/core/management/base.py", line 486, in check
[36mbackend_1   |[0m     all_issues = checks.run_checks(
[36mbackend_1   |[0m                  ^^^^^^^^^^^^^^^^^^
[36mbackend_1   |[0m   File "/usr/local/lib/python3.12/site-packages/django/core/checks/registry.py", line 88, in run_checks
[36mbackend_1   |[0m     new_errors = check(app_configs=app_configs, databases=databases)
[36mbackend_1   |[0m                  ^^^^^^^^^^^^^^^^^^^^^^^^^^^^^^^^^^^^^^^^^^^^^^^^^^^
[36mbackend_1   |[0m   File "/usr/local/lib/python3.12/site-packages/django/core/checks/model_checks.py", line 36, in check_all_models
[36mbackend_1   |[0m     errors.extend(model.check(**kwargs))
[36mbackend_1   |[0m                   ^^^^^^^^^^^^^^^^^^^^^
[36mbackend_1   |[0m   File "/usr/local/lib/python3.12/site-packages/django/db/models/base.py", line 1610, in check
[36mbackend_1   |[0m     *cls._check_constraints(databases),
[36mbackend_1   |[0m      ^^^^^^^^^^^^^^^^^^^^^^^^^^^^^^^^^
[36mbackend_1   |[0m   File "/usr/local/lib/python3.12/site-packages/django/db/models/base.py", line 2460, in _check_constraints
[36mbackend_1   |[0m     connection.features.supports_nulls_distinct_unique_constraints
[36mbackend_1   |[0m   File "/usr/local/lib/python3.12/site-packages/django/utils/functional.py", line 47, in __get__
[36mbackend_1   |[0m     res = instance.__dict__[self.name] = self.func(instance)
[36mbackend_1   |[0m                                          ^^^^^^^^^^^^^^^^^^^
[36mbackend_1   |[0m   File "/usr/local/lib/python3.12/site-packages/django/db/backends/postgresql/features.py", line 141, in is_postgresql_15
[36mbackend_1   |[0m     return self.connection.pg_version >= 150000
[36mbackend_1   |[0m            ^^^^^^^^^^^^^^^^^^^^^^^^^^
[36mbackend_1   |[0m   File "/usr/local/lib/python3.12/site-packages/django/utils/functional.py", line 47, in __get__
[36mbackend_1   |[0m     res = instance.__dict__[self.name] = self.func(instance)
[36mbackend_1   |[0m                                          ^^^^^^^^^^^^^^^^^^^
[36mbackend_1   |[0m   File "/usr/local/lib/python3.12/site-packages/django/db/backends/postgresql/base.py", line 438, in pg_version
[36mbackend_1   |[0m     with self.temporary_connection():
[36mbackend_1   |[0m   File "/usr/local/lib/python3.12/contextlib.py", line 137, in __enter__
[36mbackend_1   |[0m     return next(self.gen)
[36mbackend_1   |[0m            ^^^^^^^^^^^^^^
[36mbackend_1   |[0m   File "/usr/local/lib/python3.12/site-packages/django/db/backends/base/base.py", line 691, in temporary_connection
[36mbackend_1   |[0m     with self.cursor() as cursor:
[36mbackend_1   |[0m          ^^^^^^^^^^^^^
[36mbackend_1   |[0m   File "/usr/local/lib/python3.12/site-packages/django/utils/asyncio.py", line 26, in inner
[36mbackend_1   |[0m     return func(*args, **kwargs)
[36mbackend_1   |[0m            ^^^^^^^^^^^^^^^^^^^^^
[36mbackend_1   |[0m   File "/usr/local/lib/python3.12/site-packages/django/db/backends/base/base.py", line 316, in cursor
[36mbackend_1   |[0m     return self._cursor()
[36mbackend_1   |[0m            ^^^^^^^^^^^^^^
[36mbackend_1   |[0m   File "/usr/local/lib/python3.12/site-packages/django/db/backends/base/base.py", line 292, in _cursor
[36mbackend_1   |[0m     self.ensure_connection()
[36mbackend_1   |[0m   File "/usr/local/lib/python3.12/site-packages/django/utils/asyncio.py", line 26, in inner
[36mbackend_1   |[0m     return func(*args, **kwargs)
[36mbackend_1   |[0m            ^^^^^^^^^^^^^^^^^^^^^
[36mbackend_1   |[0m   File "/usr/local/lib/python3.12/site-packages/django/db/backends/base/base.py", line 274, in ensure_connection
[36mbackend_1   |[0m     with self.wrap_database_errors:
[36mbackend_1   |[0m   File "/usr/local/lib/python3.12/site-packages/django/db/utils.py", line 91, in __exit__
[36mbackend_1   |[0m     raise dj_exc_value.with_traceback(traceback) from exc_value
[36mbackend_1   |[0m   File "/usr/local/lib/python3.12/site-packages/django/db/backends/base/base.py", line 275, in ensure_connection
[36mbackend_1   |[0m     self.connect()
[36mbackend_1   |[0m   File "/usr/local/lib/python3.12/site-packages/django/utils/asyncio.py", line 26, in inner
[36mbackend_1   |[0m     return func(*args, **kwargs)
[36mbackend_1   |[0m            ^^^^^^^^^^^^^^^^^^^^^
[36mbackend_1   |[0m   File "/usr/local/lib/python3.12/site-packages/django/db/backends/base/base.py", line 256, in connect
[36mbackend_1   |[0m     self.connection = self.get_new_connection(conn_params)
[36mbackend_1   |[0m                       ^^^^^^^^^^^^^^^^^^^^^^^^^^^^^^^^^^^^
[36mbackend_1   |[0m   File "/usr/local/lib/python3.12/site-packages/django/utils/asyncio.py", line 26, in inner
[36mbackend_1   |[0m     return func(*args, **kwargs)
[36mbackend_1   |[0m            ^^^^^^^^^^^^^^^^^^^^^
[36mbackend_1   |[0m   File "/usr/local/lib/python3.12/site-packages/django/db/backends/postgresql/base.py", line 277, in get_new_connection
[36mbackend_1   |[0m     connection = self.Database.connect(**conn_params)
[36mbackend_1   |[0m                  ^^^^^^^^^^^^^^^^^^^^^^^^^^^^^^^^^^^^
[36mbackend_1   |[0m   File "/usr/local/lib/python3.12/site-packages/psycopg2/__init__.py", line 122, in connect
[36mbackend_1   |[0m     conn = _connect(dsn, connection_factory=connection_factory, **kwasync)
[36mbackend_1   |[0m            ^^^^^^^^^^^^^^^^^^^^^^^^^^^^^^^^^^^^^^^^^^^^^^^^^^^^^^^^^^^^^^^
[36mbackend_1   |[0m django.db.utils.OperationalError: connection to server at "localhost" (127.0.0.1), port 5432 failed: Connection refused
[36mbackend_1   |[0m 	Is the server running on that host and accepting TCP/IP connections?
[36mbackend_1   |[0m connection to server at "localhost" (::1), port 5432 failed: Cannot assign requested address
[36mbackend_1   |[0m 	Is the server running on that host and accepting TCP/IP connections?
[36mbackend_1   |[0m 
[36mbackend_1   |[0m /usr/local/lib/python3.12/site-packages/django/core/management/commands/makemigrations.py:160: RuntimeWarning: Got an error checking a consistent migration history performed for database connection 'default': connection to server at "localhost" (127.0.0.1), port 5432 failed: Connection refused
[36mbackend_1   |[0m 	Is the server running on that host and accepting TCP/IP connections?
[36mbackend_1   |[0m connection to server at "localhost" (::1), port 5432 failed: Cannot assign requested address
[36mbackend_1   |[0m 	Is the server running on that host and accepting TCP/IP connections?
[36mbackend_1   |[0m 
[36mbackend_1   |[0m   warnings.warn(
[36mbackend_1   |[0m No changes detected
[36mbackend_1   |[0m Traceback (most recent call last):
[36mbackend_1   |[0m   File "/usr/local/lib/python3.12/site-packages/django/db/backends/base/base.py", line 275, in ensure_connection
[36mbackend_1   |[0m     self.connect()
[36mbackend_1   |[0m   File "/usr/local/lib/python3.12/site-packages/django/utils/asyncio.py", line 26, in inner
[36mbackend_1   |[0m     return func(*args, **kwargs)
[36mbackend_1   |[0m            ^^^^^^^^^^^^^^^^^^^^^
[36mbackend_1   |[0m   File "/usr/local/lib/python3.12/site-packages/django/db/backends/base/base.py", line 256, in connect
[36mbackend_1   |[0m     self.connection = self.get_new_connection(conn_params)
[36mbackend_1   |[0m                       ^^^^^^^^^^^^^^^^^^^^^^^^^^^^^^^^^^^^
[36mbackend_1   |[0m   File "/usr/local/lib/python3.12/site-packages/django/utils/asyncio.py", line 26, in inner
[36mbackend_1   |[0m     return func(*args, **kwargs)
[36mbackend_1   |[0m            ^^^^^^^^^^^^^^^^^^^^^
[36mbackend_1   |[0m   File "/usr/local/lib/python3.12/site-packages/django/db/backends/postgresql/base.py", line 277, in get_new_connection
[36mbackend_1   |[0m     connection = self.Database.connect(**conn_params)
[36mbackend_1   |[0m                  ^^^^^^^^^^^^^^^^^^^^^^^^^^^^^^^^^^^^
[36mbackend_1   |[0m   File "/usr/local/lib/python3.12/site-packages/psycopg2/__init__.py", line 122, in connect
[36mbackend_1   |[0m     conn = _connect(dsn, connection_factory=connection_factory, **kwasync)
[36mbackend_1   |[0m            ^^^^^^^^^^^^^^^^^^^^^^^^^^^^^^^^^^^^^^^^^^^^^^^^^^^^^^^^^^^^^^^
[36mbackend_1   |[0m psycopg2.OperationalError: connection to server at "localhost" (127.0.0.1), port 5432 failed: Connection refused
[36mbackend_1   |[0m 	Is the server running on that host and accepting TCP/IP connections?
[36mbackend_1   |[0m connection to server at "localhost" (::1), port 5432 failed: Cannot assign requested address
[36mbackend_1   |[0m 	Is the server running on that host and accepting TCP/IP connections?
[36mbackend_1   |[0m 
[36mbackend_1   |[0m 
[36mbackend_1   |[0m The above exception was the direct cause of the following exception:
[36mbackend_1   |[0m 
[36mbackend_1   |[0m Traceback (most recent call last):
[36mbackend_1   |[0m   File "/app/manage.py", line 22, in <module>
[36mbackend_1   |[0m     main()
[36mbackend_1   |[0m   File "/app/manage.py", line 18, in main
[36mbackend_1   |[0m     execute_from_command_line(sys.argv)
[36mbackend_1   |[0m   File "/usr/local/lib/python3.12/site-packages/django/core/management/__init__.py", line 442, in execute_from_command_line
[36mbackend_1   |[0m     utility.execute()
[36mbackend_1   |[0m   File "/usr/local/lib/python3.12/site-packages/django/core/management/__init__.py", line 436, in execute
[36mbackend_1   |[0m     self.fetch_command(subcommand).run_from_argv(self.argv)
[36mbackend_1   |[0m   File "/usr/local/lib/python3.12/site-packages/django/core/management/base.py", line 413, in run_from_argv
[36mbackend_1   |[0m     self.execute(*args, **cmd_options)
[36mbackend_1   |[0m   File "/usr/local/lib/python3.12/site-packages/django/core/management/base.py", line 459, in execute
[36mbackend_1   |[0m     output = self.handle(*args, **options)
[36mbackend_1   |[0m              ^^^^^^^^^^^^^^^^^^^^^^^^^^^^^
[36mbackend_1   |[0m   File "/usr/local/lib/python3.12/site-packages/django/core/management/base.py", line 107, in wrapper
[36mbackend_1   |[0m     res = handle_func(*args, **kwargs)
[36mbackend_1   |[0m           ^^^^^^^^^^^^^^^^^^^^^^^^^^^^
[36mbackend_1   |[0m   File "/usr/local/lib/python3.12/site-packages/django/core/management/commands/migrate.py", line 100, in handle
[36mbackend_1   |[0m     self.check(databases=[database])
[36mbackend_1   |[0m   File "/usr/local/lib/python3.12/site-packages/django/core/management/base.py", line 486, in check
[36mbackend_1   |[0m     all_issues = checks.run_checks(
[36mbackend_1   |[0m                  ^^^^^^^^^^^^^^^^^^
[36mbackend_1   |[0m   File "/usr/local/lib/python3.12/site-packages/django/core/checks/registry.py", line 88, in run_checks
[36mbackend_1   |[0m     new_errors = check(app_configs=app_configs, databases=databases)
[36mbackend_1   |[0m                  ^^^^^^^^^^^^^^^^^^^^^^^^^^^^^^^^^^^^^^^^^^^^^^^^^^^
[36mbackend_1   |[0m   File "/usr/local/lib/python3.12/site-packages/django/core/checks/model_checks.py", line 36, in check_all_models
[36mbackend_1   |[0m     errors.extend(model.check(**kwargs))
[36mbackend_1   |[0m                   ^^^^^^^^^^^^^^^^^^^^^
[36mbackend_1   |[0m   File "/usr/local/lib/python3.12/site-packages/django/db/models/base.py", line 1610, in check
[36mbackend_1   |[0m     *cls._check_constraints(databases),
[36mbackend_1   |[0m      ^^^^^^^^^^^^^^^^^^^^^^^^^^^^^^^^^
[36mbackend_1   |[0m   File "/usr/local/lib/python3.12/site-packages/django/db/models/base.py", line 2460, in _check_constraints
[36mbackend_1   |[0m     connection.features.supports_nulls_distinct_unique_constraints
[36mbackend_1   |[0m   File "/usr/local/lib/python3.12/site-packages/django/utils/functional.py", line 47, in __get__
[36mbackend_1   |[0m     res = instance.__dict__[self.name] = self.func(instance)
[36mbackend_1   |[0m                                          ^^^^^^^^^^^^^^^^^^^
[36mbackend_1   |[0m   File "/usr/local/lib/python3.12/site-packages/django/db/backends/postgresql/features.py", line 141, in is_postgresql_15
[36mbackend_1   |[0m     return self.connection.pg_version >= 150000
[36mbackend_1   |[0m            ^^^^^^^^^^^^^^^^^^^^^^^^^^
[36mbackend_1   |[0m   File "/usr/local/lib/python3.12/site-packages/django/utils/functional.py", line 47, in __get__
[36mbackend_1   |[0m     res = instance.__dict__[self.name] = self.func(instance)
[36mbackend_1   |[0m                                          ^^^^^^^^^^^^^^^^^^^
[36mbackend_1   |[0m   File "/usr/local/lib/python3.12/site-packages/django/db/backends/postgresql/base.py", line 438, in pg_version
[36mbackend_1   |[0m     with self.temporary_connection():
[36mbackend_1   |[0m   File "/usr/local/lib/python3.12/contextlib.py", line 137, in __enter__
[36mbackend_1   |[0m     return next(self.gen)
[36mbackend_1   |[0m            ^^^^^^^^^^^^^^
[36mbackend_1   |[0m   File "/usr/local/lib/python3.12/site-packages/django/db/backends/base/base.py", line 691, in temporary_connection
[36mbackend_1   |[0m     with self.cursor() as cursor:
[36mbackend_1   |[0m          ^^^^^^^^^^^^^
[36mbackend_1   |[0m   File "/usr/local/lib/python3.12/site-packages/django/utils/asyncio.py", line 26, in inner
[36mbackend_1   |[0m     return func(*args, **kwargs)
[36mbackend_1   |[0m            ^^^^^^^^^^^^^^^^^^^^^
[36mbackend_1   |[0m   File "/usr/local/lib/python3.12/site-packages/django/db/backends/base/base.py", line 316, in cursor
[36mbackend_1   |[0m     return self._cursor()
[36mbackend_1   |[0m            ^^^^^^^^^^^^^^
[36mbackend_1   |[0m   File "/usr/local/lib/python3.12/site-packages/django/db/backends/base/base.py", line 292, in _cursor
[36mbackend_1   |[0m     self.ensure_connection()
[36mbackend_1   |[0m   File "/usr/local/lib/python3.12/site-packages/django/utils/asyncio.py", line 26, in inner
[36mbackend_1   |[0m     return func(*args, **kwargs)
[36mbackend_1   |[0m            ^^^^^^^^^^^^^^^^^^^^^
[36mbackend_1   |[0m   File "/usr/local/lib/python3.12/site-packages/django/db/backends/base/base.py", line 274, in ensure_connection
[36mbackend_1   |[0m     with self.wrap_database_errors:
[36mbackend_1   |[0m   File "/usr/local/lib/python3.12/site-packages/django/db/utils.py", line 91, in __exit__
[36mbackend_1   |[0m     raise dj_exc_value.with_traceback(traceback) from exc_value
[36mbackend_1   |[0m   File "/usr/local/lib/python3.12/site-packages/django/db/backends/base/base.py", line 275, in ensure_connection
[36mbackend_1   |[0m     self.connect()
[36mbackend_1   |[0m   File "/usr/local/lib/python3.12/site-packages/django/utils/asyncio.py", line 26, in inner
[36mbackend_1   |[0m     return func(*args, **kwargs)
[36mbackend_1   |[0m            ^^^^^^^^^^^^^^^^^^^^^
[36mbackend_1   |[0m   File "/usr/local/lib/python3.12/site-packages/django/db/backends/base/base.py", line 256, in connect
[36mbackend_1   |[0m     self.connection = self.get_new_connection(conn_params)
[36mbackend_1   |[0m                       ^^^^^^^^^^^^^^^^^^^^^^^^^^^^^^^^^^^^
[36mbackend_1   |[0m   File "/usr/local/lib/python3.12/site-packages/django/utils/asyncio.py", line 26, in inner
[36mbackend_1   |[0m     return func(*args, **kwargs)
[36mbackend_1   |[0m            ^^^^^^^^^^^^^^^^^^^^^
[36mbackend_1   |[0m   File "/usr/local/lib/python3.12/site-packages/django/db/backends/postgresql/base.py", line 277, in get_new_connection
[36mbackend_1   |[0m     connection = self.Database.connect(**conn_params)
[36mbackend_1   |[0m                  ^^^^^^^^^^^^^^^^^^^^^^^^^^^^^^^^^^^^
[36mbackend_1   |[0m   File "/usr/local/lib/python3.12/site-packages/psycopg2/__init__.py", line 122, in connect
[36mbackend_1   |[0m     conn = _connect(dsn, connection_factory=connection_factory, **kwasync)
[36mbackend_1   |[0m            ^^^^^^^^^^^^^^^^^^^^^^^^^^^^^^^^^^^^^^^^^^^^^^^^^^^^^^^^^^^^^^^
[36mbackend_1   |[0m django.db.utils.OperationalError: connection to server at "localhost" (127.0.0.1), port 5432 failed: Connection refused
[36mbackend_1   |[0m 	Is the server running on that host and accepting TCP/IP connections?
[36mbackend_1   |[0m connection to server at "localhost" (::1), port 5432 failed: Cannot assign requested address
[36mbackend_1   |[0m 	Is the server running on that host and accepting TCP/IP connections?
[36mbackend_1   |[0m 
